Workbook
Name ModuleList: Dashboard!$A$46:$A$89

Sheet Dashboard
A1: 📊 MEDICAL SRS — DASHBOARD · bird's-eye view of every semester & module
A2: AT A GLANCE
A3: 📚 Total lessons | B3: =COUNTA('lesson-database'!$E$3:$E$2000)
A4: ✏️ Started | B4: =COUNTA('lesson-database'!$F$3:$F$2000)
A5: ✅ Mastered | B5: =COUNTIF('lesson-database'!$G$3:$G$2000,5)
A6: ⏳ In progress | B6: =B4-B5
A7: 🔴 Overdue | B7: =COUNTIF('lesson-database'!$J$3:$J$2000,"*OVERDUE*")
A8: 🟢 Due today | B8: =COUNTIF('lesson-database'!$J$3:$J$2000,"*TODAY*")
A9: 📅 Due this week | B9: =COUNTIF('lesson-database'!$J$3:$J$2000,"*THIS WEEK*")
A10: 📈 % Complete | B10: =IF(B3=0,0,B5/B3)
A12: BY SEMESTER | H12: MASTERY MIX
A13: Semester | B13: Total | C13: Started | D13: Mastered | E13: Overdue | F13: % Done | H13: Mastery | I13: Lessons
A14: S1 | B14: =COUNTIF('lesson-database'!$B$3:$B$2000,$A14) | C14: =COUNTIFS('lesson-database'!$B$3:$B$2000,$A14,'lesson-database'!$F$3:$F$2000,"<>") | D14: =COUNTIFS('lesson-database'!$B$3:$B$2000,$A14,'lesson-database'!$G$3:$G$2000,5) | E14: =COUNTIFS('lesson-database'!$B$3:$B$2000,$A14,'lesson-database'!$J$3:$J$2000,"*OVERDUE*") | F14: =IF($B14=0,0,$D14/$B14) | H14: 0 | I14: =COUNTIF('lesson-database'!$G$3:$G$2000,$H14)
A15: S2 | B15: =COUNTIF('lesson-database'!$B$3:$B$2000,$A15) | C15: =COUNTIFS('lesson-database'!$B$3:$B$2000,$A15,'lesson-database'!$F$3:$F$2000,"<>") | D15: =COUNTIFS('lesson-database'!$B$3:$B$2000,$A15,'lesson-database'!$G$3:$G$2000,5) | E15: =COUNTIFS('lesson-database'!$B$3:$B$2000,$A15,'lesson-database'!$J$3:$J$2000,"*OVERDUE*") | F15: =IF($B15=0,0,$D15/$B15) | H15: 1 | I15: =COUNTIF('lesson-database'!$G$3:$G$2000,$H15)
A16: S3 | B16: =COUNTIF('lesson-database'!$B$3:$B$2000,$A16) | C16: =COUNTIFS('lesson-database'!$B$3:$B$2000,$A16,'lesson-database'!$F$3:$F$2000,"<>") | D16: =COUNTIFS('lesson-database'!$B$3:$B$2000,$A16,'lesson-database'!$G$3:$G$2000,5) | E16: =COUNTIFS('lesson-database'!$B$3:$B$2000,$A16,'lesson-database'!$J$3:$J$2000,"*OVERDUE*") | F16: =IF($B16=0,0,$D16/$B16) | H16: 2 | I16: =COUNTIF('lesson-database'!$G$3:$G$2000,$H16)
A17: S4 | B17: =COUNTIF('lesson-database'!$B$3:$B$2000,$A17) | C17: =COUNTIFS('lesson-database'!$B$3:$B$2000,$A17,'lesson-database'!$F$3:$F$2000,"<>") | D17: =COUNTIFS('lesson-database'!$B$3:$B$2000,$A17,'lesson-database'!$G$3:$G$2000,5) | E17: =COUNTIFS('lesson-database'!$B$3:$B$2000,$A17,'lesson-database'!$J$3:$J$2000,"*OVERDUE*") | F17: =IF($B17=0,0,$D17/$B17) | H17: 3 | I17: =COUNTIF('lesson-database'!$G$3:$G$2000,$H17)
A18: S5 | B18: =COUNTIF('lesson-database'!$B$3:$B$2000,$A18) | C18: =COUNTIFS('lesson-database'!$B$3:$B$2000,$A18,'lesson-database'!$F$3:$F$2000,"<>") | D18: =COUNTIFS('lesson-database'!$B$3:$B$2000,$A18,'lesson-database'!$G$3:$G$2000,5) | E18: =COUNTIFS('lesson-database'!$B$3:$B$2000,$A18,'lesson-database'!$J$3:$J$2000,"*OVERDUE*") | F18: =IF($B18=0,0,$D18/$B18) | H18: 4 | I18: =COUNTIF('lesson-database'!$G$3:$G$2000,$H18)
A19: S6 | B19: =COUNTIF('lesson-database'!$B$3:$B$2000,$A19) | C19: =COUNTIFS('lesson-database'!$B$3:$B$2000,$A19,'lesson-database'!$F$3:$F$2000,"<>") | D19: =COUNTIFS('lesson-database'!$B$3:$B$2000,$A19,'lesson-database'!$G$3:$G$2000,5) | E19: =COUNTIFS('lesson-database'!$B$3:$B$2000,$A19,'lesson-database'!$J$3:$J$2000,"*OVERDUE*") | F19: =IF($B19=0,0,$D19/$B19) | H19: 5 | I19: =COUNTIF('lesson-database'!$G$3:$G$2000,$H19)
A20: S7 | B20: =COUNTIF('lesson-database'!$B$3:$B$2000,$A20) | C20: =COUNTIFS('lesson-database'!$B$3:$B$2000,$A20,'lesson-database'!$F$3:$F$2000,"<>") | D20: =COUNTIFS('lesson-database'!$B$3:$B$2000,$A20,'lesson-database'!$G$3:$G$2000,5) | E20: =COUNTIFS('lesson-database'!$B$3:$B$2000,$A20,'lesson-database'!$J$3:$J$2000,"*OVERDUE*") | F20: =IF($B20=0,0,$D20/$B20)
A21: S8 | B21: =COUNTIF('lesson-database'!$B$3:$B$2000,$A21) | C21: =COUNTIFS('lesson-database'!$B$3:$B$2000,$A21,'lesson-database'!$F$3:$F$2000,"<>") | D21: =COUNTIFS('lesson-database'!$B$3:$B$2000,$A21,'lesson-database'!$G$3:$G$2000,5) | E21: =COUNTIFS('lesson-database'!$B$3:$B$2000,$A21,'lesson-database'!$J$3:$J$2000,"*OVERDUE*") | F21: =IF($B21=0,0,$D21/$B21)
A22: S9 | B22: =COUNTIF('lesson-database'!$B$3:$B$2000,$A22) | C22: =COUNTIFS('lesson-database'!$B$3:$B$2000,$A22,'lesson-database'!$F$3:$F$2000,"<>") | D22: =COUNTIFS('lesson-database'!$B$3:$B$2000,$A22,'lesson-database'!$G$3:$G$2000,5) | E22: =COUNTIFS('lesson-database'!$B$3:$B$2000,$A22,'lesson-database'!$J$3:$J$2000,"*OVERDUE*") | F22: =IF($B22=0,0,$D22/$B22)
A23: S10 | B23: =COUNTIF('lesson-database'!$B$3:$B$2000,$A23) | C23: =COUNTIFS('lesson-database'!$B$3:$B$2000,$A23,'lesson-database'!$F$3:$F$2000,"<>") | D23: =COUNTIFS('lesson-database'!$B$3:$B$2000,$A23,'lesson-database'!$G$3:$G$2000,5) | E23: =COUNTIFS('lesson-database'!$B$3:$B$2000,$A23,'lesson-database'!$J$3:$J$2000,"*OVERDUE*") | F23: =IF($B23=0,0,$D23/$B23)
A44: BY MODULE (filter the lesson-database tab, or use the Module View tab for a detailed view)
A45: Module (pick this in Module View) | B45: Sem | C45: Module name | D45: Total | E45: Started | F45: Mastered | G45: Overdue | H45: % Done
A46: S1 — Anatomie I | B46: S1 | C46: Anatomie I | D46: =COUNTIFS('lesson-database'!$B$3:$B$2000,$B46,'lesson-database'!$C$3:$C$2000,$C46) | E46: =COUNTIFS('lesson-database'!$B$3:$B$2000,$B46,'lesson-database'!$C$3:$C$2000,$C46,'lesson-database'!$F$3:$F$2000,"<>") | F46: =COUNTIFS('lesson-database'!$B$3:$B$2000,$B46,'lesson-database'!$C$3:$C$2000,$C46,'lesson-database'!$G$3:$G$2000,5) | G46: =COUNTIFS('lesson-database'!$B$3:$B$2000,$B46,'lesson-database'!$C$3:$C$2000,$C46,'lesson-database'!$J$3:$J$2000,"*OVERDUE*") | H46: =IF($D46=0,0,$F46/$D46)
A47: S1 — Santé publique | B47: S1 | C47: Santé publique | D47: =COUNTIFS('lesson-database'!$B$3:$B$2000,$B47,'lesson-database'!$C$3:$C$2000,$C47) | E47: =COUNTIFS('lesson-database'!$B$3:$B$2000,$B47,'lesson-database'!$C$3:$C$2000,$C47,'lesson-database'!$F$3:$F$2000,"<>") | F47: =COUNTIFS('lesson-database'!$B$3:$B$2000,$B47,'lesson-database'!$C$3:$C$2000,$C47,'lesson-database'!$G$3:$G$2000,5) | G47: =COUNTIFS('lesson-database'!$B$3:$B$2000,$B47,'lesson-database'!$C$3:$C$2000,$C47,'lesson-database'!$J$3:$J$2000,"*OVERDUE*") | H47: =IF($D47=0,0,$F47/$D47)
A48: S1 — Biochimie | B48: S1 | C48: Biochimie | D48: =COUNTIFS('lesson-database'!$B$3:$B$2000,$B48,'lesson-database'!$C$3:$C$2000,$C48) | E48: =COUNTIFS('lesson-database'!$B$3:$B$2000,$B48,'lesson-database'!$C$3:$C$2000,$C48,'lesson-database'!$F$3:$F$2000,"<>") | F48: =COUNTIFS('lesson-database'!$B$3:$B$2000,$B48,'lesson-database'!$C$3:$C$2000,$C48,'lesson-database'!$G$3:$G$2000,5) | G48: =COUNTIFS('lesson-database'!$B$3:$B$2000,$B48,'lesson-database'!$C$3:$C$2000,$C48,'lesson-database'!$J$3:$J$2000,"*OVERDUE*") | H48: =IF($D48=0,0,$F48/$D48)
A49: S1 — Biologie | B49: S1 | C49: Biologie | D49: =COUNTIFS('lesson-database'!$B$3:$B$2000,$B49,'lesson-database'!$C$3:$C$2000,$C49) | E49: =COUNTIFS('lesson-database'!$B$3:$B$2000,$B49,'lesson-database'!$C$3:$C$2000,$C49,'lesson-database'!$F$3:$F$2000,"<>") | F49: =COUNTIFS('lesson-database'!$B$3:$B$2000,$B49,'lesson-database'!$C$3:$C$2000,$C49,'lesson-database'!$G$3:$G$2000,5) | G49: =COUNTIFS('lesson-database'!$B$3:$B$2000,$B49,'lesson-database'!$C$3:$C$2000,$C49,'lesson-database'!$J$3:$J$2000,"*OVERDUE*") | H49: =IF($D49=0,0,$F49/$D49)
A50: S1 — TICE - Recherche médicale et anglais médical | B50: S1 | C50: TICE - Recherche médicale et anglais médical | D50: =COUNTIFS('lesson-database'!$B$3:$B$2000,$B50,'lesson-database'!$C$3:$C$2000,$C50) | E50: =COUNTIFS('lesson-database'!$B$3:$B$2000,$B50,'lesson-database'!$C$3:$C$2000,$C50,'lesson-database'!$F$3:$F$2000,"<>") | F50: =COUNTIFS('lesson-database'!$B$3:$B$2000,$B50,'lesson-database'!$C$3:$C$2000,$C50,'lesson-database'!$G$3:$G$2000,5) | G50: =COUNTIFS('lesson-database'!$B$3:$B$2000,$B50,'lesson-database'!$C$3:$C$2000,$C50,'lesson-database'!$J$3:$J$2000,"*OVERDUE*") | H50: =IF($D50=0,0,$F50/$D50)
A51: S1 — Méthodologie d'apprentissage - Terminologie | B51: S1 | C51: Méthodologie d'apprentissage - Terminologie | D51: =COUNTIFS('lesson-database'!$B$3:$B$2000,$B51,'lesson-database'!$C$3:$C$2000,$C51) | E51: =COUNTIFS('lesson-database'!$B$3:$B$2000,$B51,'lesson-database'!$C$3:$C$2000,$C51,'lesson-database'!$F$3:$F$2000,"<>") | F51: =COUNTIFS('lesson-database'!$B$3:$B$2000,$B51,'lesson-database'!$C$3:$C$2000,$C51,'lesson-database'!$G$3:$G$2000,5) | G51: =COUNTIFS('lesson-database'!$B$3:$B$2000,$B51,'lesson-database'!$C$3:$C$2000,$C51,'lesson-database'!$J$3:$J$2000,"*OVERDUE*") | H51: =IF($D51=0,0,$F51/$D51)
A52: S2 — Anatomie II | B52: S2 | C52: Anatomie II | D52: =COUNTIFS('lesson-database'!$B$3:$B$2000,$B52,'lesson-database'!$C$3:$C$2000,$C52) | E52: =COUNTIFS('lesson-database'!$B$3:$B$2000,$B52,'lesson-database'!$C$3:$C$2000,$C52,'lesson-database'!$F$3:$F$2000,"<>") | F52: =COUNTIFS('lesson-database'!$B$3:$B$2000,$B52,'lesson-database'!$C$3:$C$2000,$C52,'lesson-database'!$G$3:$G$2000,5) | G52: =COUNTIFS('lesson-database'!$B$3:$B$2000,$B52,'lesson-database'!$C$3:$C$2000,$C52,'lesson-database'!$J$3:$J$2000,"*OVERDUE*") | H52: =IF($D52=0,0,$F52/$D52)
A53: S2 — Histologie-Embryologie I | B53: S2 | C53: Histologie-Embryologie I | D53: =COUNTIFS('lesson-database'!$B$3:$B$2000,$B53,'lesson-database'!$C$3:$C$2000,$C53) | E53: =COUNTIFS('lesson-database'!$B$3:$B$2000,$B53,'lesson-database'!$C$3:$C$2000,$C53,'lesson-database'!$F$3:$F$2000,"<>") | F53: =COUNTIFS('lesson-database'!$B$3:$B$2000,$B53,'lesson-database'!$C$3:$C$2000,$C53,'lesson-database'!$G$3:$G$2000,5) | G53: =COUNTIFS('lesson-database'!$B$3:$B$2000,$B53,'lesson-database'!$C$3:$C$2000,$C53,'lesson-database'!$J$3:$J$2000,"*OVERDUE*") | H53: =IF($D53=0,0,$F53/$D53)
A54: S2 — Biophysique | B54: S2 | C54: Biophysique | D54: =COUNTIFS('lesson-database'!$B$3:$B$2000,$B54,'lesson-database'!$C$3:$C$2000,$C54) | E54: =COUNTIFS('lesson-database'!$B$3:$B$2000,$B54,'lesson-database'!$C$3:$C$2000,$C54,'lesson-database'!$F$3:$F$2000,"<>") | F54: =COUNTIFS('lesson-database'!$B$3:$B$2000,$B54,'lesson-database'!$C$3:$C$2000,$C54,'lesson-database'!$G$3:$G$2000,5) | G54: =COUNTIFS('lesson-database'!$B$3:$B$2000,$B54,'lesson-database'!$C$3:$C$2000,$C54,'lesson-database'!$J$3:$J$2000,"*OVERDUE*") | H54: =IF($D54=0,0,$F54/$D54)
A55: S2 — Histoire et psycho-social | B55: S2 | C55: Histoire et psycho-social | D55: =COUNTIFS('lesson-database'!$B$3:$B$2000,$B55,'lesson-database'!$C$3:$C$2000,$C55) | E55: =COUNTIFS('lesson-database'!$B$3:$B$2000,$B55,'lesson-database'!$C$3:$C$2000,$C55,'lesson-database'!$F$3:$F$2000,"<>") | F55: =COUNTIFS('lesson-database'!$B$3:$B$2000,$B55,'lesson-database'!$C$3:$C$2000,$C55,'lesson-database'!$G$3:$G$2000,5) | G55: =COUNTIFS('lesson-database'!$B$3:$B$2000,$B55,'lesson-database'!$C$3:$C$2000,$C55,'lesson-database'!$J$3:$J$2000,"*OVERDUE*") | H55: =IF($D55=0,0,$F55/$D55)
A56: S3 — Sémiologie I | B56: S3 | C56: Sémiologie I | D56: =COUNTIFS('lesson-database'!$B$3:$B$2000,$B56,'lesson-database'!$C$3:$C$2000,$C56) | E56: =COUNTIFS('lesson-database'!$B$3:$B$2000,$B56,'lesson-database'!$C$3:$C$2000,$C56,'lesson-database'!$F$3:$F$2000,"<>") | F56: =COUNTIFS('lesson-database'!$B$3:$B$2000,$B56,'lesson-database'!$C$3:$C$2000,$C56,'lesson-database'!$G$3:$G$2000,5) | G56: =COUNTIFS('lesson-database'!$B$3:$B$2000,$B56,'lesson-database'!$C$3:$C$2000,$C56,'lesson-database'!$J$3:$J$2000,"*OVERDUE*") | H56: =IF($D56=0,0,$F56/$D56)
A57: S3 — Anatomie III | B57: S3 | C57: Anatomie III | D57: =COUNTIFS('lesson-database'!$B$3:$B$2000,$B57,'lesson-database'!$C$3:$C$2000,$C57) | E57: =COUNTIFS('lesson-database'!$B$3:$B$2000,$B57,'lesson-database'!$C$3:$C$2000,$C57,'lesson-database'!$F$3:$F$2000,"<>") | F57: =COUNTIFS('lesson-database'!$B$3:$B$2000,$B57,'lesson-database'!$C$3:$C$2000,$C57,'lesson-database'!$G$3:$G$2000,5) | G57: =COUNTIFS('lesson-database'!$B$3:$B$2000,$B57,'lesson-database'!$C$3:$C$2000,$C57,'lesson-database'!$J$3:$J$2000,"*OVERDUE*") | H57: =IF($D57=0,0,$F57/$D57)
... A89: S10 — Synthèse thérapeutique | B89: S10 | C89: Synthèse thérapeutique | D89: =COUNTIFS('lesson-database'!$B$3:$B$2000,$B89,'lesson-database'!$C$3:$C$2000,$C89) | E89: =COUNTIFS('lesson-database'!$B$3:$B$2000,$B89,'lesson-database'!$C$3:$C$2000,$C89,'lesson-database'!$F$3:$F$2000,"<>") | F89: =COUNTIFS('lesson-database'!$B$3:$B$2000,$B89,'lesson-database'!$C$3:$C$2000,$C89,'lesson-database'!$G$3:$G$2000,5) | G89: =COUNTIFS('lesson-database'!$B$3:$B$2000,$B89,'lesson-database'!$C$3:$C$2000,$C89,'lesson-database'!$J$3:$J$2000,"*OVERDUE*") | H89: =IF($D89=0,0,$F89/$D89)

Sheet lesson-database
A1: 🧠 MEDICAL SRS — type only F & G · ▼ filters on row 2 | E1: =TODAY() | F1: =MAX(0,$K$1-TODAY()) | I1: 🎯 Exam date: | K1: 46154
A2: # | B2: Semester | C2: Module | D2: Subject | E2: Lesson | F2: Last Review | G2: Mastery | H2: Interval | I2: Next Review | J2: Status | K2: Priority | L2: Synced | M2: Event ID
A3: =ROW()-2 | B3: S1 | C3: Anatomie I | E3: Généralités en anatomie | H3: =IF($G3="",1,IF($G3=0,1,IF($G3=1,3,IF($G3=2,7,IF($G3=3,14,IF($G3=4,30,60)))))) | I3: =IF($F3="","",$F3+$H3) | J3: =IF($F3="","⚪ NEW",IF($G3>=5,"✅ DONE",IF($I3<TODAY(),"🔴 OVERDUE",IF($I3=TODAY(),"🟢 TODAY",IF($I3=TODAY()+1,"🔵 TOMORROW",IF($I3<=TODAY()+7,"📅 THIS WEEK","⏳ SCHEDULED")))))) | K3: =IF($F3="",999,IF($G3>=5,9999,IF($I3="",999,$I3-TODAY())))
A4: =ROW()-2 | B4: S1 | C4: Anatomie I | E4: Ostéo-arthrologie du membre supérieur | H4: =IF($G4="",1,IF($G4=0,1,IF($G4=1,3,IF($G4=2,7,IF($G4=3,14,IF($G4=4,30,60)))))) | I4: =IF($F4="","",$F4+$H4) | J4: =IF($F4="","⚪ NEW",IF($G4>=5,"✅ DONE",IF($I4<TODAY(),"🔴 OVERDUE",IF($I4=TODAY(),"🟢 TODAY",IF($I4=TODAY()+1,"🔵 TOMORROW",IF($I4<=TODAY()+7,"📅 THIS WEEK","⏳ SCHEDULED")))))) | K4: =IF($F4="",999,IF($G4>=5,9999,IF($I4="",999,$I4-TODAY())))
A5: =ROW()-2 | B5: S1 | C5: Anatomie I | E5: Ostéologie de l'épaule et du bras | H5: =IF($G5="",1,IF($G5=0,1,IF($G5=1,3,IF($G5=2,7,IF($G5=3,14,IF($G5=4,30,60)))))) | I5: =IF($F5="","",$F5+$H5) | J5: =IF($F5="","⚪ NEW",IF($G5>=5,"✅ DONE",IF($I5<TODAY(),"🔴 OVERDUE",IF($I5=TODAY(),"🟢 TODAY",IF($I5=TODAY()+1,"🔵 TOMORROW",IF($I5<=TODAY()+7,"📅 THIS WEEK","⏳ SCHEDULED")))))) | K5: =IF($F5="",999,IF($G5>=5,9999,IF($I5="",999,$I5-TODAY())))
A6: =ROW()-2 | B6: S1 | C6: Anatomie I | E6: Ostéologie du coude et de l'avant-bras | H6: =IF($G6="",1,IF($G6=0,1,IF($G6=1,3,IF($G6=2,7,IF($G6=3,14,IF($G6=4,30,60)))))) | I6: =IF($F6="","",$F6+$H6) | J6: =IF($F6="","⚪ NEW",IF($G6>=5,"✅ DONE",IF($I6<TODAY(),"🔴 OVERDUE",IF($I6=TODAY(),"🟢 TODAY",IF($I6=TODAY()+1,"🔵 TOMORROW",IF($I6<=TODAY()+7,"📅 THIS WEEK","⏳ SCHEDULED")))))) | K6: =IF($F6="",999,IF($G6>=5,9999,IF($I6="",999,$I6-TODAY())))
A7: =ROW()-2 | B7: S1 | C7: Anatomie I | E7: Ostéologie de la main et du poignet | H7: =IF($G7="",1,IF($G7=0,1,IF($G7=1,3,IF($G7=2,7,IF($G7=3,14,IF($G7=4,30,60)))))) | I7: =IF($F7="","",$F7+$H7) | J7: =IF($F7="","⚪ NEW",IF($G7>=5,"✅ DONE",IF($I7<TODAY(),"🔴 OVERDUE",IF($I7=TODAY(),"🟢 TODAY",IF($I7=TODAY()+1,"🔵 TOMORROW",IF($I7<=TODAY()+7,"📅 THIS WEEK","⏳ SCHEDULED")))))) | K7: =IF($F7="",999,IF($G7>=5,9999,IF($I7="",999,$I7-TODAY())))
A8: =ROW()-2 | B8: S1 | C8: Anatomie I | E8: Myologie du membre supérieur | H8: =IF($G8="",1,IF($G8=0,1,IF($G8=1,3,IF($G8=2,7,IF($G8=3,14,IF($G8=4,30,60)))))) | I8: =IF($F8="","",$F8+$H8) | J8: =IF($F8="","⚪ NEW",IF($G8>=5,"✅ DONE",IF($I8<TODAY(),"🔴 OVERDUE",IF($I8=TODAY(),"🟢 TODAY",IF($I8=TODAY()+1,"🔵 TOMORROW",IF($I8<=TODAY()+7,"📅 THIS WEEK","⏳ SCHEDULED")))))) | K8: =IF($F8="",999,IF($G8>=5,9999,IF($I8="",999,$I8-TODAY())))
A9: =ROW()-2 | B9: S1 | C9: Anatomie I | E9: Myologie de l'épaule et du bras | H9: =IF($G9="",1,IF($G9=0,1,IF($G9=1,3,IF($G9=2,7,IF($G9=3,14,IF($G9=4,30,60)))))) | I9: =IF($F9="","",$F9+$H9) | J9: =IF($F9="","⚪ NEW",IF($G9>=5,"✅ DONE",IF($I9<TODAY(),"🔴 OVERDUE",IF($I9=TODAY(),"🟢 TODAY",IF($I9=TODAY()+1,"🔵 TOMORROW",IF($I9<=TODAY()+7,"📅 THIS WEEK","⏳ SCHEDULED")))))) | K9: =IF($F9="",999,IF($G9>=5,9999,IF($I9="",999,$I9-TODAY())))
A10: =ROW()-2 | B10: S1 | C10: Anatomie I | E10: Myologie de l'avant-bras | H10: =IF($G10="",1,IF($G10=0,1,IF($G10=1,3,IF($G10=2,7,IF($G10=3,14,IF($G10=4,30,60)))))) | I10: =IF($F10="","",$F10+$H10) | J10: =IF($F10="","⚪ NEW",IF($G10>=5,"✅ DONE",IF($I10<TODAY(),"🔴 OVERDUE",IF($I10=TODAY(),"🟢 TODAY",IF($I10=TODAY()+1,"🔵 TOMORROW",IF($I10<=TODAY()+7,"📅 THIS WEEK","⏳ SCHEDULED")))))) | K10: =IF($F10="",999,IF($G10>=5,9999,IF($I10="",999,$I10-TODAY())))
A11: =ROW()-2 | B11: S1 | C11: Anatomie I | E11: Myologie de la main | H11: =IF($G11="",1,IF($G11=0,1,IF($G11=1,3,IF($G11=2,7,IF($G11=3,14,IF($G11=4,30,60)))))) | I11: =IF($F11="","",$F11+$H11) | J11: =IF($F11="","⚪ NEW",IF($G11>=5,"✅ DONE",IF($I11<TODAY(),"🔴 OVERDUE",IF($I11=TODAY(),"🟢 TODAY",IF($I11=TODAY()+1,"🔵 TOMORROW",IF($I11<=TODAY()+7,"📅 THIS WEEK","⏳ SCHEDULED")))))) | K11: =IF($F11="",999,IF($G11>=5,9999,IF($I11="",999,$I11-TODAY())))
A12: =ROW()-2 | B12: S1 | C12: Anatomie I | E12: Ostéo-arthrologie du membre inférieur | H12: =IF($G12="",1,IF($G12=0,1,IF($G12=1,3,IF($G12=2,7,IF($G12=3,14,IF($G12=4,30,60)))))) | I12: =IF($F12="","",$F12+$H12) | J12: =IF($F12="","⚪ NEW",IF($G12>=5,"✅ DONE",IF($I12<TODAY(),"🔴 OVERDUE",IF($I12=TODAY(),"🟢 TODAY",IF($I12=TODAY()+1,"🔵 TOMORROW",IF($I12<=TODAY()+7,"📅 THIS WEEK","⏳ SCHEDULED")))))) | K12: =IF($F12="",999,IF($G12>=5,9999,IF($I12="",999,$I12-TODAY())))
A13: =ROW()-2 | B13: S1 | C13: Anatomie I | E13: Os coxal, fémur et articulation de la hanche | H13: =IF($G13="",1,IF($G13=0,1,IF($G13=1,3,IF($G13=2,7,IF($G13=3,14,IF($G13=4,30,60)))))) | I13: =IF($F13="","",$F13+$H13) | J13: =IF($F13="","⚪ NEW",IF($G13>=5,"✅ DONE",IF($I13<TODAY(),"🔴 OVERDUE",IF($I13=TODAY(),"🟢 TODAY",IF($I13=TODAY()+1,"🔵 TOMORROW",IF($I13<=TODAY()+7,"📅 THIS WEEK","⏳ SCHEDULED")))))) | K13: =IF($F13="",999,IF($G13>=5,9999,IF($I13="",999,$I13-TODAY())))
A14: =ROW()-2 | B14: S1 | C14: Anatomie I | E14: Tibia, fibula, patella et articulation du genou | H14: =IF($G14="",1,IF($G14=0,1,IF($G14=1,3,IF($G14=2,7,IF($G14=3,14,IF($G14=4,30,60)))))) | I14: =IF($F14="","",$F14+$H14) | J14: =IF($F14="","⚪ NEW",IF($G14>=5,"✅ DONE",IF($I14<TODAY(),"🔴 OVERDUE",IF($I14=TODAY(),"🟢 TODAY",IF($I14=TODAY()+1,"🔵 TOMORROW",IF($I14<=TODAY()+7,"📅 THIS WEEK","⏳ SCHEDULED")))))) | K14: =IF($F14="",999,IF($G14>=5,9999,IF($I14="",999,$I14-TODAY())))
... A31: =ROW()-2 | B31: S1 | C31: Anatomie I | E31: Le médiastin postérieur | H31: =IF($G31="",1,IF($G31=0,1,IF($G31=1,3,IF($G31=2,7,IF($G31=3,14,IF($G31=4,30,60)))))) | I31: =IF($F31="","",$F31+$H31) | J31: =IF($F31="","⚪ NEW",IF($G31>=5,"✅ DONE",IF($I31<TODAY(),"🔴 OVERDUE",IF($I31=TODAY(),"🟢 TODAY",IF($I31=TODAY()+1,"🔵 TOMORROW",IF($I31<=TODAY()+7,"📅 THIS WEEK","⏳ SCHEDULED")))))) | K31: =IF($F31="",999,IF($G31>=5,9999,IF($I31="",999,$I31-TODAY())))
A32: =ROW()-2 | B32: S1 | C32: Santé publique | D32: Médecine communautaire | E32: Système de soins au Maroc (partie 1) | H32: =IF($G32="",1,IF($G32=0,1,IF($G32=1,3,IF($G32=2,7,IF($G32=3,14,IF($G32=4,30,60)))))) | I32: =IF($F32="","",$F32+$H32) | J32: =IF($F32="","⚪ NEW",IF($G32>=5,"✅ DONE",IF($I32<TODAY(),"🔴 OVERDUE",IF($I32=TODAY(),"🟢 TODAY",IF($I32=TODAY()+1,"🔵 TOMORROW",IF($I32<=TODAY()+7,"📅 THIS WEEK","⏳ SCHEDULED")))))) | K32: =IF($F32="",999,IF($G32>=5,9999,IF($I32="",999,$I32-TODAY())))
A33: =ROW()-2 | B33: S1 | C33: Santé publique | D33: Médecine communautaire | E33: Système de soins au Maroc (partie 2) | H33: =IF($G33="",1,IF($G33=0,1,IF($G33=1,3,IF($G33=2,7,IF($G33=3,14,IF($G33=4,30,60)))))) | I33: =IF($F33="","",$F33+$H33) | J33: =IF($F33="","⚪ NEW",IF($G33>=5,"✅ DONE",IF($I33<TODAY(),"🔴 OVERDUE",IF($I33=TODAY(),"🟢 TODAY",IF($I33=TODAY()+1,"🔵 TOMORROW",IF($I33<=TODAY()+7,"📅 THIS WEEK","⏳ SCHEDULED")))))) | K33: =IF($F33="",999,IF($G33>=5,9999,IF($I33="",999,$I33-TODAY())))
A34: =ROW()-2 | B34: S1 | C34: Santé publique | D34: Médecine communautaire | E34: Prévention de la maladie | H34: =IF($G34="",1,IF($G34=0,1,IF($G34=1,3,IF($G34=2,7,IF($G34=3,14,IF($G34=4,30,60)))))) | I34: =IF($F34="","",$F34+$H34) | J34: =IF($F34="","⚪ NEW",IF($G34>=5,"✅ DONE",IF($I34<TODAY(),"🔴 OVERDUE",IF($I34=TODAY(),"🟢 TODAY",IF($I34=TODAY()+1,"🔵 TOMORROW",IF($I34<=TODAY()+7,"📅 THIS WEEK","⏳ SCHEDULED")))))) | K34: =IF($F34="",999,IF($G34>=5,9999,IF($I34="",999,$I34-TODAY())))
A35: =ROW()-2 | B35: S1 | C35: Santé publique | D35: Médecine communautaire | E35: Hygiène hospitalière | H35: =IF($G35="",1,IF($G35=0,1,IF($G35=1,3,IF($G35=2,7,IF($G35=3,14,IF($G35=4,30,60)))))) | I35: =IF($F35="","",$F35+$H35) | J35: =IF($F35="","⚪ NEW",IF($G35>=5,"✅ DONE",IF($I35<TODAY(),"🔴 OVERDUE",IF($I35=TODAY(),"🟢 TODAY",IF($I35=TODAY()+1,"🔵 TOMORROW",IF($I35<=TODAY()+7,"📅 THIS WEEK","⏳ SCHEDULED")))))) | K35: =IF($F35="",999,IF($G35>=5,9999,IF($I35="",999,$I35-TODAY())))
A36: =ROW()-2 | B36: S1 | C36: Santé publique | D36: Médecine communautaire | E36: Concepts fondamentaux de santé publique | H36: =IF($G36="",1,IF($G36=0,1,IF($G36=1,3,IF($G36=2,7,IF($G36=3,14,IF($G36=4,30,60)))))) | I36: =IF($F36="","",$F36+$H36) | J36: =IF($F36="","⚪ NEW",IF($G36>=5,"✅ DONE",IF($I36<TODAY(),"🔴 OVERDUE",IF($I36=TODAY(),"🟢 TODAY",IF($I36=TODAY()+1,"🔵 TOMORROW",IF($I36<=TODAY()+7,"📅 THIS WEEK","⏳ SCHEDULED")))))) | K36: =IF($F36="",999,IF($G36>=5,9999,IF($I36="",999,$I36-TODAY())))
A37: =ROW()-2 | B37: S1 | C37: Santé publique | D37: Médecine communautaire | E37: Fonctions de santé publique | H37: =IF($G37="",1,IF($G37=0,1,IF($G37=1,3,IF($G37=2,7,IF($G37=3,14,IF($G37=4,30,60)))))) | I37: =IF($F37="","",$F37+$H37) | J37: =IF($F37="","⚪ NEW",IF($G37>=5,"✅ DONE",IF($I37<TODAY(),"🔴 OVERDUE",IF($I37=TODAY(),"🟢 TODAY",IF($I37=TODAY()+1,"🔵 TOMORROW",IF($I37<=TODAY()+7,"📅 THIS WEEK","⏳ SCHEDULED")))))) | K37: =IF($F37="",999,IF($G37>=5,9999,IF($I37="",999,$I37-TODAY())))
A38: =ROW()-2 | B38: S1 | C38: Santé publique | D38: Médecine communautaire | E38: Indicateurs de santé d'une population | H38: =IF($G38="",1,IF($G38=0,1,IF($G38=1,3,IF($G38=2,7,IF($G38=3,14,IF($G38=4,30,60)))))) | I38: =IF($F38="","",$F38+$H38) | J38: =IF($F38="","⚪ NEW",IF($G38>=5,"✅ DONE",IF($I38<TODAY(),"🔴 OVERDUE",IF($I38=TODAY(),"🟢 TODAY",IF($I38=TODAY()+1,"🔵 TOMORROW",IF($I38<=TODAY()+7,"📅 THIS WEEK","⏳ SCHEDULED")))))) | K38: =IF($F38="",999,IF($G38>=5,9999,IF($I38="",999,$I38-TODAY())))
A39: =ROW()-2 | B39: S1 | C39: Santé publique | D39: Médecine communautaire | E39: Problèmes de santé dans le monde | H39: =IF($G39="",1,IF($G39=0,1,IF($G39=1,3,IF($G39=2,7,IF($G39=3,14,IF($G39=4,30,60)))))) | I39: =IF($F39="","",$F39+$H39) | J39: =IF($F39="","⚪ NEW",IF($G39>=5,"✅ DONE",IF($I39<TODAY(),"🔴 OVERDUE",IF($I39=TODAY(),"🟢 TODAY",IF($I39=TODAY()+1,"🔵 TOMORROW",IF($I39<=TODAY()+7,"📅 THIS WEEK","⏳ SCHEDULED")))))) | K39: =IF($F39="",999,IF($G39>=5,9999,IF($I39="",999,$I39-TODAY())))
A40: =ROW()-2 | B40: S1 | C40: Santé publique | D40: Biostatistiques | E40: Principes de base en biostatistiques | H40: =IF($G40="",1,IF($G40=0,1,IF($G40=1,3,IF($G40=2,7,IF($G40=3,14,IF($G40=4,30,60)))))) | I40: =IF($F40="","",$F40+$H40) | J40: =IF($F40="","⚪ NEW",IF($G40>=5,"✅ DONE",IF($I40<TODAY(),"🔴 OVERDUE",IF($I40=TODAY(),"🟢 TODAY",IF($I40=TODAY()+1,"🔵 TOMORROW",IF($I40<=TODAY()+7,"📅 THIS WEEK","⏳ SCHEDULED")))))) | K40: =IF($F40="",999,IF($G40>=5,9999,IF($I40="",999,$I40-TODAY())))
A41: =ROW()-2 | B41: S1 | C41: Santé publique | D41: Biostatistiques | E41: Présentation des données | H41: =IF($G41="",1,IF($G41=0,1,IF($G41=1,3,IF($G41=2,7,IF($G41=3,14,IF($G41=4,30,60)))))) | I41: =IF($F41="","",$F41+$H41) | J41: =IF($F41="","⚪ NEW",IF($G41>=5,"✅ DONE",IF($I41<TODAY(),"🔴 OVERDUE",IF($I41=TODAY(),"🟢 TODAY",IF($I41=TODAY()+1,"🔵 TOMORROW",IF($I41<=TODAY()+7,"📅 THIS WEEK","⏳ SCHEDULED")))))) | K41: =IF($F41="",999,IF($G41>=5,9999,IF($I41="",999,$I41-TODAY())))
A42: =ROW()-2 | B42: S1 | C42: Santé publique | D42: Biostatistiques | E42: Statistiques descriptives | H42: =IF($G42="",1,IF($G42=0,1,IF($G42=1,3,IF($G42=2,7,IF($G42=3,14,IF($G42=4,30,60)))))) | I42: =IF($F42="","",$F42+$H42) | J42: =IF($F42="","⚪ NEW",IF($G42>=5,"✅ DONE",IF($I42<TODAY(),"🔴 OVERDUE",IF($I42=TODAY(),"🟢 TODAY",IF($I42=TODAY()+1,"🔵 TOMORROW",IF($I42<=TODAY()+7,"📅 THIS WEEK","⏳ SCHEDULED")))))) | K42: =IF($F42="",999,IF($G42>=5,9999,IF($I42="",999,$I42-TODAY())))
A43: =ROW()-2 | B43: S1 | C43: Santé publique | D43: Biostatistiques | E43: Principes de base de l'épidémiologie | H43: =IF($G43="",1,IF($G43=0,1,IF($G43=1,3,IF($G43=2,7,IF($G43=3,14,IF($G43=4,30,60)))))) | I43: =IF($F43="","",$F43+$H43) | J43: =IF($F43="","⚪ NEW",IF($G43>=5,"✅ DONE",IF($I43<TODAY(),"🔴 OVERDUE",IF($I43=TODAY(),"🟢 TODAY",IF($I43=TODAY()+1,"🔵 TOMORROW",IF($I43<=TODAY()+7,"📅 THIS WEEK","⏳ SCHEDULED")))))) | K43: =IF($F43="",999,IF($G43>=5,9999,IF($I43="",999,$I43-TODAY())))
... A89: =ROW()-2 | B89: S1 | C89: Biologie | D89: Génétique | E89: Génétique chromosomique : caryotype | H89: =IF($G89="",1,IF($G89=0,1,IF($G89=1,3,IF($G89=2,7,IF($G89=3,14,IF($G89=4,30,60)))))) | I89: =IF($F89="","",$F89+$H89) | J89: =IF($F89="","⚪ NEW",IF($G89>=5,"✅ DONE",IF($I89<TODAY(),"🔴 OVERDUE",IF($I89=TODAY(),"🟢 TODAY",IF($I89=TODAY()+1,"🔵 TOMORROW",IF($I89<=TODAY()+7,"📅 THIS WEEK","⏳ SCHEDULED")))))) | K89: =IF($F89="",999,IF($G89>=5,9999,IF($I89="",999,$I89-TODAY())))
A90: =ROW()-2 | B90: S1 | C90: TICE - Recherche médicale et anglais médical | E90: Introduction au TICE | H90: =IF($G90="",1,IF($G90=0,1,IF($G90=1,3,IF($G90=2,7,IF($G90=3,14,IF($G90=4,30,60)))))) | I90: =IF($F90="","",$F90+$H90) | J90: =IF($F90="","⚪ NEW",IF($G90>=5,"✅ DONE",IF($I90<TODAY(),"🔴 OVERDUE",IF($I90=TODAY(),"🟢 TODAY",IF($I90=TODAY()+1,"🔵 TOMORROW",IF($I90<=TODAY()+7,"📅 THIS WEEK","⏳ SCHEDULED")))))) | K90: =IF($F90="",999,IF($G90>=5,9999,IF($I90="",999,$I90-TODAY())))
A91: =ROW()-2 | B91: S1 | C91: TICE - Recherche médicale et anglais médical | E91: Séances de TD | H91: =IF($G91="",1,IF($G91=0,1,IF($G91=1,3,IF($G91=2,7,IF($G91=3,14,IF($G91=4,30,60)))))) | I91: =IF($F91="","",$F91+$H91) | J91: =IF($F91="","⚪ NEW",IF($G91>=5,"✅ DONE",IF($I91<TODAY(),"🔴 OVERDUE",IF($I91=TODAY(),"🟢 TODAY",IF($I91=TODAY()+1,"🔵 TOMORROW",IF($I91<=TODAY()+7,"📅 THIS WEEK","⏳ SCHEDULED")))))) | K91: =IF($F91="",999,IF($G91>=5,9999,IF($I91="",999,$I91-TODAY())))
A92: =ROW()-2 | B92: S1 | C92: TICE - Recherche médicale et anglais médical | E92: Intelligence artificielle | H92: =IF($G92="",1,IF($G92=0,1,IF($G92=1,3,IF($G92=2,7,IF($G92=3,14,IF($G92=4,30,60)))))) | I92: =IF($F92="","",$F92+$H92) | J92: =IF($F92="","⚪ NEW",IF($G92>=5,"✅ DONE",IF($I92<TODAY(),"🔴 OVERDUE",IF($I92=TODAY(),"🟢 TODAY",IF($I92=TODAY()+1,"🔵 TOMORROW",IF($I92<=TODAY()+7,"📅 THIS WEEK","⏳ SCHEDULED")))))) | K92: =IF($F92="",999,IF($G92>=5,9999,IF($I92="",999,$I92-TODAY())))
A93: =ROW()-2 | B93: S1 | C93: TICE - Recherche médicale et anglais médical | E93: Traitement d'images | H93: =IF($G93="",1,IF($G93=0,1,IF($G93=1,3,IF($G93=2,7,IF($G93=3,14,IF($G93=4,30,60)))))) | I93: =IF($F93="","",$F93+$H93) | J93: =IF($F93="","⚪ NEW",IF($G93>=5,"✅ DONE",IF($I93<TODAY(),"🔴 OVERDUE",IF($I93=TODAY(),"🟢 TODAY",IF($I93=TODAY()+1,"🔵 TOMORROW",IF($I93<=TODAY()+7,"📅 THIS WEEK","⏳ SCHEDULED")))))) | K93: =IF($F93="",999,IF($G93>=5,9999,IF($I93="",999,$I93-TODAY())))
A94: =ROW()-2 | B94: S1 | C94: TICE - Recherche médicale et anglais médical | E94: L'internet des objets | H94: =IF($G94="",1,IF($G94=0,1,IF($G94=1,3,IF($G94=2,7,IF($G94=3,14,IF($G94=4,30,60)))))) | I94: =IF($F94="","",$F94+$H94) | J94: =IF($F94="","⚪ NEW",IF($G94>=5,"✅ DONE",IF($I94<TODAY(),"🔴 OVERDUE",IF($I94=TODAY(),"🟢 TODAY",IF($I94=TODAY()+1,"🔵 TOMORROW",IF($I94<=TODAY()+7,"📅 THIS WEEK","⏳ SCHEDULED")))))) | K94: =IF($F94="",999,IF($G94>=5,9999,IF($I94="",999,$I94-TODAY())))
A95: =ROW()-2 | B95: S1 | C95: TICE - Recherche médicale et anglais médical | E95: La réalité virtuelle | H95: =IF($G95="",1,IF($G95=0,1,IF($G95=1,3,IF($G95=2,7,IF($G95=3,14,IF($G95=4,30,60)))))) | I95: =IF($F95="","",$F95+$H95) | J95: =IF($F95="","⚪ NEW",IF($G95>=5,"✅ DONE",IF($I95<TODAY(),"🔴 OVERDUE",IF($I95=TODAY(),"🟢 TODAY",IF($I95=TODAY()+1,"🔵 TOMORROW",IF($I95<=TODAY()+7,"📅 THIS WEEK","⏳ SCHEDULED")))))) | K95: =IF($F95="",999,IF($G95>=5,9999,IF($I95="",999,$I95-TODAY())))
A96: =ROW()-2 | B96: S1 | C96: TICE - Recherche médicale et anglais médical | E96: La télémédecine | H96: =IF($G96="",1,IF($G96=0,1,IF($G96=1,3,IF($G96=2,7,IF($G96=3,14,IF($G96=4,30,60)))))) | I96: =IF($F96="","",$F96+$H96) | J96: =IF($F96="","⚪ NEW",IF($G96>=5,"✅ DONE",IF($I96<TODAY(),"🔴 OVERDUE",IF($I96=TODAY(),"🟢 TODAY",IF($I96=TODAY()+1,"🔵 TOMORROW",IF($I96<=TODAY()+7,"📅 THIS WEEK","⏳ SCHEDULED")))))) | K96: =IF($F96="",999,IF($G96>=5,9999,IF($I96="",999,$I96-TODAY())))
A97: =ROW()-2 | B97: S1 | C97: Méthodologie d'apprentissage - Terminologie | D97: Méthodologie d'apprentissage | E97: Méthodologies de l'apprentissage en médecine | H97: =IF($G97="",1,IF($G97=0,1,IF($G97=1,3,IF($G97=2,7,IF($G97=3,14,IF($G97=4,30,60)))))) | I97: =IF($F97="","",$F97+$H97) | J97: =IF($F97="","⚪ NEW",IF($G97>=5,"✅ DONE",IF($I97<TODAY(),"🔴 OVERDUE",IF($I97=TODAY(),"🟢 TODAY",IF($I97=TODAY()+1,"🔵 TOMORROW",IF($I97<=TODAY()+7,"📅 THIS WEEK","⏳ SCHEDULED")))))) | K97: =IF($F97="",999,IF($G97>=5,9999,IF($I97="",999,$I97-TODAY())))
A98: =ROW()-2 | B98: S1 | C98: Méthodologie d'apprentissage - Terminologie | D98: Méthodologie d'apprentissage | E98: Gestion du temps et outils d'apprentissage | H98: =IF($G98="",1,IF($G98=0,1,IF($G98=1,3,IF($G98=2,7,IF($G98=3,14,IF($G98=4,30,60)))))) | I98: =IF($F98="","",$F98+$H98) | J98: =IF($F98="","⚪ NEW",IF($G98>=5,"✅ DONE",IF($I98<TODAY(),"🔴 OVERDUE",IF($I98=TODAY(),"🟢 TODAY",IF($I98=TODAY()+1,"🔵 TOMORROW",IF($I98<=TODAY()+7,"📅 THIS WEEK","⏳ SCHEDULED")))))) | K98: =IF($F98="",999,IF($G98>=5,9999,IF($I98="",999,$I98-TODAY())))
A99: =ROW()-2 | B99: S1 | C99: Méthodologie d'apprentissage - Terminologie | D99: Méthodologie d'apprentissage | E99: Mémorisation et concentration | H99: =IF($G99="",1,IF($G99=0,1,IF($G99=1,3,IF($G99=2,7,IF($G99=3,14,IF($G99=4,30,60)))))) | I99: =IF($F99="","",$F99+$H99) | J99: =IF($F99="","⚪ NEW",IF($G99>=5,"✅ DONE",IF($I99<TODAY(),"🔴 OVERDUE",IF($I99=TODAY(),"🟢 TODAY",IF($I99=TODAY()+1,"🔵 TOMORROW",IF($I99<=TODAY()+7,"📅 THIS WEEK","⏳ SCHEDULED")))))) | K99: =IF($F99="",999,IF($G99>=5,9999,IF($I99="",999,$I99-TODAY())))
A100: =ROW()-2 | B100: S1 | C100: Méthodologie d'apprentissage - Terminologie | D100: Terminologie | E100: Terminologie médicale (préfixe, suffixe, racine) | H100: =IF($G100="",1,IF($G100=0,1,IF($G100=1,3,IF($G100=2,7,IF($G100=3,14,IF($G100=4,30,60)))))) | I100: =IF($F100="","",$F100+$H100) | J100: =IF($F100="","⚪ NEW",IF($G100>=5,"✅ DONE",IF($I100<TODAY(),"🔴 OVERDUE",IF($I100=TODAY(),"🟢 TODAY",IF($I100=TODAY()+1,"🔵 TOMORROW",IF($I100<=TODAY()+7,"📅 THIS WEEK","⏳ SCHEDULED")))))) | K100: =IF($F100="",999,IF($G100>=5,9999,IF($I100="",999,$I100-TODAY())))
A101: =ROW()-2 | B101: S1 | C101: Méthodologie d'apprentissage - Terminologie | D101: Terminologie | E101: Terminologie spécifique maxillo-faciale | H101: =IF($G101="",1,IF($G101=0,1,IF($G101=1,3,IF($G101=2,7,IF($G101=3,14,IF($G101=4,30,60)))))) | I101: =IF($F101="","",$F101+$H101) | J101: =IF($F101="","⚪ NEW",IF($G101>=5,"✅ DONE",IF($I101<TODAY(),"🔴 OVERDUE",IF($I101=TODAY(),"🟢 TODAY",IF($I101=TODAY()+1,"🔵 TOMORROW",IF($I101<=TODAY()+7,"📅 THIS WEEK","⏳ SCHEDULED")))))) | K101: =IF($F101="",999,IF($G101>=5,9999,IF($I101="",999,$I101-TODAY())))
...

Sheet Module View
A1: 🔍 MODULE VIEW — pick one module to see its lessons, stats and mastery chart | N1: =IFERROR(INDEX(Dashboard!$B$46:$B$89,MATCH($C$3,Dashboard!$A$46:$A$89,0)),"")
N2: =IFERROR(INDEX(Dashboard!$C$46:$C$89,MATCH($C$3,Dashboard!$A$46:$A$89,0)),"")
A3: ▶ Module: | C3: S1 — Anatomie I
A5: THIS MODULE | H5: Mastery | I5: Lessons
A6: Total | B6: =COUNTIFS('lesson-database'!$B$3:$B$2000,$N$1,'lesson-database'!$C$3:$C$2000,$N$2) | C6: Started | D6: =COUNTIFS('lesson-database'!$B$3:$B$2000,$N$1,'lesson-database'!$C$3:$C$2000,$N$2,'lesson-database'!$F$3:$F$2000,"<>") | E6: Mastered | F6: =COUNTIFS('lesson-database'!$B$3:$B$2000,$N$1,'lesson-database'!$C$3:$C$2000,$N$2,'lesson-database'!$G$3:$G$2000,5) | H6: 0 | I6: =COUNTIFS('lesson-database'!$B$3:$B$2000,$N$1,'lesson-database'!$C$3:$C$2000,$N$2,'lesson-database'!$G$3:$G$2000,$H6)
A7: Overdue | B7: =COUNTIFS('lesson-database'!$B$3:$B$2000,$N$1,'lesson-database'!$C$3:$C$2000,$N$2,'lesson-database'!$J$3:$J$2000,"*OVERDUE*") | C7: Due today | D7: =COUNTIFS('lesson-database'!$B$3:$B$2000,$N$1,'lesson-database'!$C$3:$C$2000,$N$2,'lesson-database'!$J$3:$J$2000,"*TODAY*") | E7: This week | F7: =COUNTIFS('lesson-database'!$B$3:$B$2000,$N$1,'lesson-database'!$C$3:$C$2000,$N$2,'lesson-database'!$J$3:$J$2000,"*THIS WEEK*") | H7: 1 | I7: =COUNTIFS('lesson-database'!$B$3:$B$2000,$N$1,'lesson-database'!$C$3:$C$2000,$N$2,'lesson-database'!$G$3:$G$2000,$H7)
H8: 2 | I8: =COUNTIFS('lesson-database'!$B$3:$B$2000,$N$1,'lesson-database'!$C$3:$C$2000,$N$2,'lesson-database'!$G$3:$G$2000,$H8)
H9: 3 | I9: =COUNTIFS('lesson-database'!$B$3:$B$2000,$N$1,'lesson-database'!$C$3:$C$2000,$N$2,'lesson-database'!$G$3:$G$2000,$H9)
H10: 4 | I10: =COUNTIFS('lesson-database'!$B$3:$B$2000,$N$1,'lesson-database'!$C$3:$C$2000,$N$2,'lesson-database'!$G$3:$G$2000,$H10)
H11: 5 | I11: =COUNTIFS('lesson-database'!$B$3:$B$2000,$N$1,'lesson-database'!$C$3:$C$2000,$N$2,'lesson-database'!$G$3:$G$2000,$H11)
A13: LESSONS IN THIS MODULE
A14: Lesson | B14: Last Review | C14: Mastery | D14: Interval | E14: Next Review | F14: Status | G14: Priority
A15: =IFERROR(FILTER('lesson-database'!$E$3:$K$2000,('lesson-database'!$B$3:$B$2000=$N$1)*('lesson-database'!$C$3:$C$2000=$N$2),"— no lessons —"),"FILTER needs Excel 365 or Google Sheets — use the lesson-database tab's filter arrows instead.")

Sheet Weekly
A1: 🗓️ WEEKLY — your next 7 days of reviews
A3: Date | B3: Day | C3: Reviews | D3: Load | E3: Est. min
A4: =TODAY() | B4: =TEXT(A4,"ddd") | C4: =COUNTIF('lesson-database'!$I$3:$I$2000,A4)+COUNTIF('lesson-database'!$J$3:$J$2000,"*OVERDUE*") | D4: =IF(C4=0,"🟢 Free",IF(C4<=5,"🟢 Light",IF(C4<=10,"🟡 Medium",IF(C4<=15,"🟠 Heavy","🔴 Overload")))) | E4: =C4*10
A5: =A4+1 | B5: =TEXT(A5,"ddd") | C5: =COUNTIF('lesson-database'!$I$3:$I$2000,A5) | D5: =IF(C5=0,"🟢 Free",IF(C5<=5,"🟢 Light",IF(C5<=10,"🟡 Medium",IF(C5<=15,"🟠 Heavy","🔴 Overload")))) | E5: =C5*10
A6: =A5+1 | B6: =TEXT(A6,"ddd") | C6: =COUNTIF('lesson-database'!$I$3:$I$2000,A6) | D6: =IF(C6=0,"🟢 Free",IF(C6<=5,"🟢 Light",IF(C6<=10,"🟡 Medium",IF(C6<=15,"🟠 Heavy","🔴 Overload")))) | E6: =C6*10
A7: =A6+1 | B7: =TEXT(A7,"ddd") | C7: =COUNTIF('lesson-database'!$I$3:$I$2000,A7) | D7: =IF(C7=0,"🟢 Free",IF(C7<=5,"🟢 Light",IF(C7<=10,"🟡 Medium",IF(C7<=15,"🟠 Heavy","🔴 Overload")))) | E7: =C7*10
A8: =A7+1 | B8: =TEXT(A8,"ddd") | C8: =COUNTIF('lesson-database'!$I$3:$I$2000,A8) | D8: =IF(C8=0,"🟢 Free",IF(C8<=5,"🟢 Light",IF(C8<=10,"🟡 Medium",IF(C8<=15,"🟠 Heavy","🔴 Overload")))) | E8: =C8*10
A9: =A8+1 | B9: =TEXT(A9,"ddd") | C9: =COUNTIF('lesson-database'!$I$3:$I$2000,A9) | D9: =IF(C9=0,"🟢 Free",IF(C9<=5,"🟢 Light",IF(C9<=10,"🟡 Medium",IF(C9<=15,"🟠 Heavy","🔴 Overload")))) | E9: =C9*10
A10: =A9+1 | B10: =TEXT(A10,"ddd") | C10: =COUNTIF('lesson-database'!$I$3:$I$2000,A10) | D10: =IF(C10=0,"🟢 Free",IF(C10<=5,"🟢 Light",IF(C10<=10,"🟡 Medium",IF(C10<=15,"🟠 Heavy","🔴 Overload")))) | E10: =C10*10

Sheet How-To
A1: 🧠 MEDICAL SRS — HOW TO USE
A3: THE ONE RULE: you only ever type in two columns on the lesson-database tab —
A4: • F Last Review → the day you studied it (press Ctrl+; for today)
A5: • G Mastery → how well you recalled it, 0 (forgot) to 5 (mastered)
A6: Everything else (interval, next review, status, priority) fills in by itself.
A7: Top bar (row 1): today + days left until the exam — set your exam date in the blue K1 cell.
A8: Rows are tinted per module (same color = same module) for easier scanning.
A10: HOW THE SCHEDULE WORKS
A11: Mastery 0→review in 1 day · 1→3d · 2→7d · 3→14d · 4→30d · 5→done (drops off).
A12: Forgot it? set 0 and it comes back tomorrow. Solid? a higher score pushes it out.
A14: FILTERING (quick filter)
A15: lesson-database tab → click the ▼ arrow on row 2 of Semester, Module or Subject.
... A26: Tip: the Module View lesson list uses FILTER — needs Excel 365 or Google Sheets.
