Workbook

Sheet 📖 Guide
A1: 📖 QUICK START GUIDE
A3: ⚡ DAILY WORKFLOW (10 SECONDS PER CARD)
A5: 1️⃣ Open "⚡ TODAY" sheet
A6: → See compact list (no gaps!) of due lessons
A7: → Note the ROW# in column A
A9: 2️⃣ For each lesson:
A10: a) Study the material
A11: b) Rate difficulty:
A12: 😊 Easy = "I nailed this, skip ahead!"
A13: 👍 Good = "Got it, normal progress"
A14: 😐 Hard = "Tough, review again same level"
A15: 🔴 Again = "Need more practice, go back"
... A37: 📊 DIFFICULTY SYSTEM
A38: Level | B38: Base Interval | C38: Easy Topic (×1.3) | D38: Hard Topic (×0.7)
A39: 0 | B39: 0 days | C39: 0 days | D39: 0 days
A40: 1 | B40: 1 day | C40: 1 day | D40: 1 day
A41: 2 | B41: 3 days | C41: 4 days | D41: 2 days
A42: 3 | B42: 7 days | C42: 9 days | D42: 5 days
A43: 4 | B43: 15 days | C43: 20 days | D43: 11 days
A44: 5 | B44: 30 days | C44: 39 days | D44: 21 days
A45: 6 | B45: 60 days | C45: 78 days | D45: 42 days
A46: 7 | B46: 90 days | C46: 117 days | D46: 63 days

Sheet ⚡ TODAY
A1: ⚡ TODAY'S REVIEWS
A2: Due Now: | B2: =COUNTIFS(Database!$G:$G,"<="&TODAY(),Database!$A:$A,"<>""")+(COUNTIF(Database!$E:$E,"")-COUNTBLANK(Database!$A:$A)) -> 3
A3: ✅ SIMPLE: Study → Rate → Mark DONE → Row GREEN → Use ROW# to find lesson in Database → Update Level & Date → Done!
A4: ROW# | B4: Lesson | C4: Current Level | D4: Last Review | E4: Due | F4: Rate Difficulty | G4: Mark | H4: New Level | I4: New Date
A5: =IF(AND(Database!A5<>"",OR(Database!G5<=TODAY(),Database!E5="")),5,"") -> 5 | B5: =IF(A5="","",Database!A5&" - "&Database!B5) -> Microbio - Viral replication | C5: =IF(A5="","","Level "&Database!D5) -> Level 0 | D5: =IF(A5="","",IF(Database!E5="","Never",TEXT(Database!E5,"DD/MM/YY"))) -> Never | E5: =IF(A5="","",IF(Database!G5="","START NOW!",IF(Database!G5<TODAY(),"OVERDUE "&ABS(Database!G5-TODAY())&"d","Today"))) -> START NOW! | H5: =IF(G5="✅ DONE", IF(F5="😊 Easy",MIN(Database!D5+2,7), IF(F5="👍 Good",MIN(Database!D5+1,7), IF(F5="😐 Hard",Database!D5, IF(F5="🔴 Again",MAX(Database!D5-1,0), "")))), "") | I5: =IF(G5="✅ DONE",TEXT(TODAY(),"DD/MM/YY"),"")
A6: =IF(AND(Database!A6<>"",OR(Database!G6<=TODAY(),Database!E6="")),6,"") | B6: =IF(A6="","",Database!A6&" - "&Database!B6) | C6: =IF(A6="","","Level "&Database!D6) | D6: =IF(A6="","",IF(Database!E6="","Never",TEXT(Database!E6,"DD/MM/YY"))) | E6: =IF(A6="","",IF(Database!G6="","START NOW!",IF(Database!G6<TODAY(),"OVERDUE "&ABS(Database!G6-TODAY())&"d","Today"))) | H6: =IF(G6="✅ DONE", IF(F6="😊 Easy",MIN(Database!D6+2,7), IF(F6="👍 Good",MIN(Database!D6+1,7), IF(F6="😐 Hard",Database!D6, IF(F6="🔴 Again",MAX(Database!D6-1,0), "")))), "") | I6: =IF(G6="✅ DONE",TEXT(TODAY(),"DD/MM/YY"),"")
A7: =IF(AND(Database!A7<>"",OR(Database!G7<=TODAY(),Database!E7="")),7,"") | B7: =IF(A7="","",Database!A7&" - "&Database!B7) | C7: =IF(A7="","","Level "&Database!D7) | D7: =IF(A7="","",IF(Database!E7="","Never",TEXT(Database!E7,"DD/MM/YY"))) | E7: =IF(A7="","",IF(Database!G7="","START NOW!",IF(Database!G7<TODAY(),"OVERDUE "&ABS(Database!G7-TODAY())&"d","Today"))) | H7: =IF(G7="✅ DONE", IF(F7="😊 Easy",MIN(Database!D7+2,7), IF(F7="👍 Good",MIN(Database!D7+1,7), IF(F7="😐 Hard",Database!D7, IF(F7="🔴 Again",MAX(Database!D7-1,0), "")))), "") | I7: =IF(G7="✅ DONE",TEXT(TODAY(),"DD/MM/YY"),"")
A8: =IF(AND(Database!A8<>"",OR(Database!G8<=TODAY(),Database!E8="")),8,"") | B8: =IF(A8="","",Database!A8&" - "&Database!B8) | C8: =IF(A8="","","Level "&Database!D8) | D8: =IF(A8="","",IF(Database!E8="","Never",TEXT(Database!E8,"DD/MM/YY"))) | E8: =IF(A8="","",IF(Database!G8="","START NOW!",IF(Database!G8<TODAY(),"OVERDUE "&ABS(Database!G8-TODAY())&"d","Today"))) | H8: =IF(G8="✅ DONE", IF(F8="😊 Easy",MIN(Database!D8+2,7), IF(F8="👍 Good",MIN(Database!D8+1,7), IF(F8="😐 Hard",Database!D8, IF(F8="🔴 Again",MAX(Database!D8-1,0), "")))), "") | I8: =IF(G8="✅ DONE",TEXT(TODAY(),"DD/MM/YY"),"")
A9: =IF(AND(Database!A9<>"",OR(Database!G9<=TODAY(),Database!E9="")),9,"") | B9: =IF(A9="","",Database!A9&" - "&Database!B9) | C9: =IF(A9="","","Level "&Database!D9) | D9: =IF(A9="","",IF(Database!E9="","Never",TEXT(Database!E9,"DD/MM/YY"))) | E9: =IF(A9="","",IF(Database!G9="","START NOW!",IF(Database!G9<TODAY(),"OVERDUE "&ABS(Database!G9-TODAY())&"d","Today"))) | H9: =IF(G9="✅ DONE", IF(F9="😊 Easy",MIN(Database!D9+2,7), IF(F9="👍 Good",MIN(Database!D9+1,7), IF(F9="😐 Hard",Database!D9, IF(F9="🔴 Again",MAX(Database!D9-1,0), "")))), "") | I9: =IF(G9="✅ DONE",TEXT(TODAY(),"DD/MM/YY"),"")
A10: =IF(AND(Database!A10<>"",OR(Database!G10<=TODAY(),Database!E10="")),10,"") | B10: =IF(A10="","",Database!A10&" - "&Database!B10) | C10: =IF(A10="","","Level "&Database!D10) | D10: =IF(A10="","",IF(Database!E10="","Never",TEXT(Database!E10,"DD/MM/YY"))) | E10: =IF(A10="","",IF(Database!G10="","START NOW!",IF(Database!G10<TODAY(),"OVERDUE "&ABS(Database!G10-TODAY())&"d","Today"))) | H10: =IF(G10="✅ DONE", IF(F10="😊 Easy",MIN(Database!D10+2,7), IF(F10="👍 Good",MIN(Database!D10+1,7), IF(F10="😐 Hard",Database!D10, IF(F10="🔴 Again",MAX(Database!D10-1,0), "")))), "") | I10: =IF(G10="✅ DONE",TEXT(TODAY(),"DD/MM/YY"),"")
A11: =IF(AND(Database!A11<>"",OR(Database!G11<=TODAY(),Database!E11="")),11,"") | B11: =IF(A11="","",Database!A11&" - "&Database!B11) | C11: =IF(A11="","","Level "&Database!D11) | D11: =IF(A11="","",IF(Database!E11="","Never",TEXT(Database!E11,"DD/MM/YY"))) | E11: =IF(A11="","",IF(Database!G11="","START NOW!",IF(Database!G11<TODAY(),"OVERDUE "&ABS(Database!G11-TODAY())&"d","Today"))) | H11: =IF(G11="✅ DONE", IF(F11="😊 Easy",MIN(Database!D11+2,7), IF(F11="👍 Good",MIN(Database!D11+1,7), IF(F11="😐 Hard",Database!D11, IF(F11="🔴 Again",MAX(Database!D11-1,0), "")))), "") | I11: =IF(G11="✅ DONE",TEXT(TODAY(),"DD/MM/YY"),"")
A12: =IF(AND(Database!A12<>"",OR(Database!G12<=TODAY(),Database!E12="")),12,"") | B12: =IF(A12="","",Database!A12&" - "&Database!B12) | C12: =IF(A12="","","Level "&Database!D12) | D12: =IF(A12="","",IF(Database!E12="","Never",TEXT(Database!E12,"DD/MM/YY"))) | E12: =IF(A12="","",IF(Database!G12="","START NOW!",IF(Database!G12<TODAY(),"OVERDUE "&ABS(Database!G12-TODAY())&"d","Today"))) | H12: =IF(G12="✅ DONE", IF(F12="😊 Easy",MIN(Database!D12+2,7), IF(F12="👍 Good",MIN(Database!D12+1,7), IF(F12="😐 Hard",Database!D12, IF(F12="🔴 Again",MAX(Database!D12-1,0), "")))), "") | I12: =IF(G12="✅ DONE",TEXT(TODAY(),"DD/MM/YY"),"")
A13: =IF(AND(Database!A13<>"",OR(Database!G13<=TODAY(),Database!E13="")),13,"") | B13: =IF(A13="","",Database!A13&" - "&Database!B13) | C13: =IF(A13="","","Level "&Database!D13) | D13: =IF(A13="","",IF(Database!E13="","Never",TEXT(Database!E13,"DD/MM/YY"))) | E13: =IF(A13="","",IF(Database!G13="","START NOW!",IF(Database!G13<TODAY(),"OVERDUE "&ABS(Database!G13-TODAY())&"d","Today"))) | H13: =IF(G13="✅ DONE", IF(F13="😊 Easy",MIN(Database!D13+2,7), IF(F13="👍 Good",MIN(Database!D13+1,7), IF(F13="😐 Hard",Database!D13, IF(F13="🔴 Again",MAX(Database!D13-1,0), "")))), "") | I13: =IF(G13="✅ DONE",TEXT(TODAY(),"DD/MM/YY"),"")
A14: =IF(AND(Database!A14<>"",OR(Database!G14<=TODAY(),Database!E14="")),14,"") | B14: =IF(A14="","",Database!A14&" - "&Database!B14) | C14: =IF(A14="","","Level "&Database!D14) | D14: =IF(A14="","",IF(Database!E14="","Never",TEXT(Database!E14,"DD/MM/YY"))) | E14: =IF(A14="","",IF(Database!G14="","START NOW!",IF(Database!G14<TODAY(),"OVERDUE "&ABS(Database!G14-TODAY())&"d","Today"))) | H14: =IF(G14="✅ DONE", IF(F14="😊 Easy",MIN(Database!D14+2,7), IF(F14="👍 Good",MIN(Database!D14+1,7), IF(F14="😐 Hard",Database!D14, IF(F14="🔴 Again",MAX(Database!D14-1,0), "")))), "") | I14: =IF(G14="✅ DONE",TEXT(TODAY(),"DD/MM/YY"),"")
A15: =IF(AND(Database!A15<>"",OR(Database!G15<=TODAY(),Database!E15="")),15,"") | B15: =IF(A15="","",Database!A15&" - "&Database!B15) | C15: =IF(A15="","","Level "&Database!D15) | D15: =IF(A15="","",IF(Database!E15="","Never",TEXT(Database!E15,"DD/MM/YY"))) | E15: =IF(A15="","",IF(Database!G15="","START NOW!",IF(Database!G15<TODAY(),"OVERDUE "&ABS(Database!G15-TODAY())&"d","Today"))) | H15: =IF(G15="✅ DONE", IF(F15="😊 Easy",MIN(Database!D15+2,7), IF(F15="👍 Good",MIN(Database!D15+1,7), IF(F15="😐 Hard",Database!D15, IF(F15="🔴 Again",MAX(Database!D15-1,0), "")))), "") | I15: =IF(G15="✅ DONE",TEXT(TODAY(),"DD/MM/YY"),"")
A16: =IF(AND(Database!A16<>"",OR(Database!G16<=TODAY(),Database!E16="")),16,"") | B16: =IF(A16="","",Database!A16&" - "&Database!B16) | C16: =IF(A16="","","Level "&Database!D16) | D16: =IF(A16="","",IF(Database!E16="","Never",TEXT(Database!E16,"DD/MM/YY"))) | E16: =IF(A16="","",IF(Database!G16="","START NOW!",IF(Database!G16<TODAY(),"OVERDUE "&ABS(Database!G16-TODAY())&"d","Today"))) | H16: =IF(G16="✅ DONE", IF(F16="😊 Easy",MIN(Database!D16+2,7), IF(F16="👍 Good",MIN(Database!D16+1,7), IF(F16="😐 Hard",Database!D16, IF(F16="🔴 Again",MAX(Database!D16-1,0), "")))), "") | I16: =IF(G16="✅ DONE",TEXT(TODAY(),"DD/MM/YY"),"")
A17: =IF(AND(Database!A17<>"",OR(Database!G17<=TODAY(),Database!E17="")),17,"") | B17: =IF(A17="","",Database!A17&" - "&Database!B17) | C17: =IF(A17="","","Level "&Database!D17) | D17: =IF(A17="","",IF(Database!E17="","Never",TEXT(Database!E17,"DD/MM/YY"))) | E17: =IF(A17="","",IF(Database!G17="","START NOW!",IF(Database!G17<TODAY(),"OVERDUE "&ABS(Database!G17-TODAY())&"d","Today"))) | H17: =IF(G17="✅ DONE", IF(F17="😊 Easy",MIN(Database!D17+2,7), IF(F17="👍 Good",MIN(Database!D17+1,7), IF(F17="😐 Hard",Database!D17, IF(F17="🔴 Again",MAX(Database!D17-1,0), "")))), "") | I17: =IF(G17="✅ DONE",TEXT(TODAY(),"DD/MM/YY"),"")
A18: =IF(AND(Database!A18<>"",OR(Database!G18<=TODAY(),Database!E18="")),18,"") | B18: =IF(A18="","",Database!A18&" - "&Database!B18) | C18: =IF(A18="","","Level "&Database!D18) | D18: =IF(A18="","",IF(Database!E18="","Never",TEXT(Database!E18,"DD/MM/YY"))) | E18: =IF(A18="","",IF(Database!G18="","START NOW!",IF(Database!G18<TODAY(),"OVERDUE "&ABS(Database!G18-TODAY())&"d","Today"))) | H18: =IF(G18="✅ DONE", IF(F18="😊 Easy",MIN(Database!D18+2,7), IF(F18="👍 Good",MIN(Database!D18+1,7), IF(F18="😐 Hard",Database!D18, IF(F18="🔴 Again",MAX(Database!D18-1,0), "")))), "") | I18: =IF(G18="✅ DONE",TEXT(TODAY(),"DD/MM/YY"),"")
A19: =IF(AND(Database!A19<>"",OR(Database!G19<=TODAY(),Database!E19="")),19,"") | B19: =IF(A19="","",Database!A19&" - "&Database!B19) | C19: =IF(A19="","","Level "&Database!D19) | D19: =IF(A19="","",IF(Database!E19="","Never",TEXT(Database!E19,"DD/MM/YY"))) | E19: =IF(A19="","",IF(Database!G19="","START NOW!",IF(Database!G19<TODAY(),"OVERDUE "&ABS(Database!G19-TODAY())&"d","Today"))) | H19: =IF(G19="✅ DONE", IF(F19="😊 Easy",MIN(Database!D19+2,7), IF(F19="👍 Good",MIN(Database!D19+1,7), IF(F19="😐 Hard",Database!D19, IF(F19="🔴 Again",MAX(Database!D19-1,0), "")))), "") | I19: =IF(G19="✅ DONE",TEXT(TODAY(),"DD/MM/YY"),"")
A20: =IF(AND(Database!A20<>"",OR(Database!G20<=TODAY(),Database!E20="")),20,"") | B20: =IF(A20="","",Database!A20&" - "&Database!B20) | C20: =IF(A20="","","Level "&Database!D20) | D20: =IF(A20="","",IF(Database!E20="","Never",TEXT(Database!E20,"DD/MM/YY"))) | E20: =IF(A20="","",IF(Database!G20="","START NOW!",IF(Database!G20<TODAY(),"OVERDUE "&ABS(Database!G20-TODAY())&"d","Today"))) | H20: =IF(G20="✅ DONE", IF(F20="😊 Easy",MIN(Database!D20+2,7), IF(F20="👍 Good",MIN(Database!D20+1,7), IF(F20="😐 Hard",Database!D20, IF(F20="🔴 Again",MAX(Database!D20-1,0), "")))), "") | I20: =IF(G20="✅ DONE",TEXT(TODAY(),"DD/MM/YY"),"")
A21: =IF(AND(Database!A21<>"",OR(Database!G21<=TODAY(),Database!E21="")),21,"") | B21: =IF(A21="","",Database!A21&" - "&Database!B21) | C21: =IF(A21="","","Level "&Database!D21) | D21: =IF(A21="","",IF(Database!E21="","Never",TEXT(Database!E21,"DD/MM/YY"))) | E21: =IF(A21="","",IF(Database!G21="","START NOW!",IF(Database!G21<TODAY(),"OVERDUE "&ABS(Database!G21-TODAY())&"d","Today"))) | H21: =IF(G21="✅ DONE", IF(F21="😊 Easy",MIN(Database!D21+2,7), IF(F21="👍 Good",MIN(Database!D21+1,7), IF(F21="😐 Hard",Database!D21, IF(F21="🔴 Again",MAX(Database!D21-1,0), "")))), "") | I21: =IF(G21="✅ DONE",TEXT(TODAY(),"DD/MM/YY"),"")
A22: =IF(AND(Database!A22<>"",OR(Database!G22<=TODAY(),Database!E22="")),22,"") | B22: =IF(A22="","",Database!A22&" - "&Database!B22) | C22: =IF(A22="","","Level "&Database!D22) | D22: =IF(A22="","",IF(Database!E22="","Never",TEXT(Database!E22,"DD/MM/YY"))) | E22: =IF(A22="","",IF(Database!G22="","START NOW!",IF(Database!G22<TODAY(),"OVERDUE "&ABS(Database!G22-TODAY())&"d","Today"))) | H22: =IF(G22="✅ DONE", IF(F22="😊 Easy",MIN(Database!D22+2,7), IF(F22="👍 Good",MIN(Database!D22+1,7), IF(F22="😐 Hard",Database!D22, IF(F22="🔴 Again",MAX(Database!D22-1,0), "")))), "") | I22: =IF(G22="✅ DONE",TEXT(TODAY(),"DD/MM/YY"),"")
A23: =IF(AND(Database!A23<>"",OR(Database!G23<=TODAY(),Database!E23="")),23,"") | B23: =IF(A23="","",Database!A23&" - "&Database!B23) | C23: =IF(A23="","","Level "&Database!D23) | D23: =IF(A23="","",IF(Database!E23="","Never",TEXT(Database!E23,"DD/MM/YY"))) | E23: =IF(A23="","",IF(Database!G23="","START NOW!",IF(Database!G23<TODAY(),"OVERDUE "&ABS(Database!G23-TODAY())&"d","Today"))) | H23: =IF(G23="✅ DONE", IF(F23="😊 Easy",MIN(Database!D23+2,7), IF(F23="👍 Good",MIN(Database!D23+1,7), IF(F23="😐 Hard",Database!D23, IF(F23="🔴 Again",MAX(Database!D23-1,0), "")))), "") | I23: =IF(G23="✅ DONE",TEXT(TODAY(),"DD/MM/YY"),"")
A24: =IF(AND(Database!A24<>"",OR(Database!G24<=TODAY(),Database!E24="")),24,"") | B24: =IF(A24="","",Database!A24&" - "&Database!B24) | C24: =IF(A24="","","Level "&Database!D24) | D24: =IF(A24="","",IF(Database!E24="","Never",TEXT(Database!E24,"DD/MM/YY"))) | E24: =IF(A24="","",IF(Database!G24="","START NOW!",IF(Database!G24<TODAY(),"OVERDUE "&ABS(Database!G24-TODAY())&"d","Today"))) | H24: =IF(G24="✅ DONE", IF(F24="😊 Easy",MIN(Database!D24+2,7), IF(F24="👍 Good",MIN(Database!D24+1,7), IF(F24="😐 Hard",Database!D24, IF(F24="🔴 Again",MAX(Database!D24-1,0), "")))), "") | I24: =IF(G24="✅ DONE",TEXT(TODAY(),"DD/MM/YY"),"")
A25: =IF(AND(Database!A25<>"",OR(Database!G25<=TODAY(),Database!E25="")),25,"") | B25: =IF(A25="","",Database!A25&" - "&Database!B25) | C25: =IF(A25="","","Level "&Database!D25) | D25: =IF(A25="","",IF(Database!E25="","Never",TEXT(Database!E25,"DD/MM/YY"))) | E25: =IF(A25="","",IF(Database!G25="","START NOW!",IF(Database!G25<TODAY(),"OVERDUE "&ABS(Database!G25-TODAY())&"d","Today"))) | H25: =IF(G25="✅ DONE", IF(F25="😊 Easy",MIN(Database!D25+2,7), IF(F25="👍 Good",MIN(Database!D25+1,7), IF(F25="😐 Hard",Database!D25, IF(F25="🔴 Again",MAX(Database!D25-1,0), "")))), "") | I25: =IF(G25="✅ DONE",TEXT(TODAY(),"DD/MM/YY"),"")
A26: =IF(AND(Database!A26<>"",OR(Database!G26<=TODAY(),Database!E26="")),26,"") | B26: =IF(A26="","",Database!A26&" - "&Database!B26) | C26: =IF(A26="","","Level "&Database!D26) | D26: =IF(A26="","",IF(Database!E26="","Never",TEXT(Database!E26,"DD/MM/YY"))) | E26: =IF(A26="","",IF(Database!G26="","START NOW!",IF(Database!G26<TODAY(),"OVERDUE "&ABS(Database!G26-TODAY())&"d","Today"))) | H26: =IF(G26="✅ DONE", IF(F26="😊 Easy",MIN(Database!D26+2,7), IF(F26="👍 Good",MIN(Database!D26+1,7), IF(F26="😐 Hard",Database!D26, IF(F26="🔴 Again",MAX(Database!D26-1,0), "")))), "") | I26: =IF(G26="✅ DONE",TEXT(TODAY(),"DD/MM/YY"),"")
A27: =IF(AND(Database!A27<>"",OR(Database!G27<=TODAY(),Database!E27="")),27,"") | B27: =IF(A27="","",Database!A27&" - "&Database!B27) | C27: =IF(A27="","","Level "&Database!D27) | D27: =IF(A27="","",IF(Database!E27="","Never",TEXT(Database!E27,"DD/MM/YY"))) | E27: =IF(A27="","",IF(Database!G27="","START NOW!",IF(Database!G27<TODAY(),"OVERDUE "&ABS(Database!G27-TODAY())&"d","Today"))) | H27: =IF(G27="✅ DONE", IF(F27="😊 Easy",MIN(Database!D27+2,7), IF(F27="👍 Good",MIN(Database!D27+1,7), IF(F27="😐 Hard",Database!D27, IF(F27="🔴 Again",MAX(Database!D27-1,0), "")))), "") | I27: =IF(G27="✅ DONE",TEXT(TODAY(),"DD/MM/YY"),"")
A28: =IF(AND(Database!A28<>"",OR(Database!G28<=TODAY(),Database!E28="")),28,"") | B28: =IF(A28="","",Database!A28&" - "&Database!B28) | C28: =IF(A28="","","Level "&Database!D28) | D28: =IF(A28="","",IF(Database!E28="","Never",TEXT(Database!E28,"DD/MM/YY"))) | E28: =IF(A28="","",IF(Database!G28="","START NOW!",IF(Database!G28<TODAY(),"OVERDUE "&ABS(Database!G28-TODAY())&"d","Today"))) | H28: =IF(G28="✅ DONE", IF(F28="😊 Easy",MIN(Database!D28+2,7), IF(F28="👍 Good",MIN(Database!D28+1,7), IF(F28="😐 Hard",Database!D28, IF(F28="🔴 Again",MAX(Database!D28-1,0), "")))), "") | I28: =IF(G28="✅ DONE",TEXT(TODAY(),"DD/MM/YY"),"")
A29: =IF(AND(Database!A29<>"",OR(Database!G29<=TODAY(),Database!E29="")),29,"") | B29: =IF(A29="","",Database!A29&" - "&Database!B29) | C29: =IF(A29="","","Level "&Database!D29) | D29: =IF(A29="","",IF(Database!E29="","Never",TEXT(Database!E29,"DD/MM/YY"))) | E29: =IF(A29="","",IF(Database!G29="","START NOW!",IF(Database!G29<TODAY(),"OVERDUE "&ABS(Database!G29-TODAY())&"d","Today"))) | H29: =IF(G29="✅ DONE", IF(F29="😊 Easy",MIN(Database!D29+2,7), IF(F29="👍 Good",MIN(Database!D29+1,7), IF(F29="😐 Hard",Database!D29, IF(F29="🔴 Again",MAX(Database!D29-1,0), "")))), "") | I29: =IF(G29="✅ DONE",TEXT(TODAY(),"DD/MM/YY"),"")
A30: =IF(AND(Database!A30<>"",OR(Database!G30<=TODAY(),Database!E30="")),30,"") | B30: =IF(A30="","",Database!A30&" - "&Database!B30) | C30: =IF(A30="","","Level "&Database!D30) | D30: =IF(A30="","",IF(Database!E30="","Never",TEXT(Database!E30,"DD/MM/YY"))) | E30: =IF(A30="","",IF(Database!G30="","START NOW!",IF(Database!G30<TODAY(),"OVERDUE "&ABS(Database!G30-TODAY())&"d","Today"))) | H30: =IF(G30="✅ DONE", IF(F30="😊 Easy",MIN(Database!D30+2,7), IF(F30="👍 Good",MIN(Database!D30+1,7), IF(F30="😐 Hard",Database!D30, IF(F30="🔴 Again",MAX(Database!D30-1,0), "")))), "") | I30: =IF(G30="✅ DONE",TEXT(TODAY(),"DD/MM/YY"),"")
A31: =IF(AND(Database!A31<>"",OR(Database!G31<=TODAY(),Database!E31="")),31,"") | B31: =IF(A31="","",Database!A31&" - "&Database!B31) | C31: =IF(A31="","","Level "&Database!D31) | D31: =IF(A31="","",IF(Database!E31="","Never",TEXT(Database!E31,"DD/MM/YY"))) | E31: =IF(A31="","",IF(Database!G31="","START NOW!",IF(Database!G31<TODAY(),"OVERDUE "&ABS(Database!G31-TODAY())&"d","Today"))) | H31: =IF(G31="✅ DONE", IF(F31="😊 Easy",MIN(Database!D31+2,7), IF(F31="👍 Good",MIN(Database!D31+1,7), IF(F31="😐 Hard",Database!D31, IF(F31="🔴 Again",MAX(Database!D31-1,0), "")))), "") | I31: =IF(G31="✅ DONE",TEXT(TODAY(),"DD/MM/YY"),"")
A32: =IF(AND(Database!A32<>"",OR(Database!G32<=TODAY(),Database!E32="")),32,"") | B32: =IF(A32="","",Database!A32&" - "&Database!B32) | C32: =IF(A32="","","Level "&Database!D32) | D32: =IF(A32="","",IF(Database!E32="","Never",TEXT(Database!E32,"DD/MM/YY"))) | E32: =IF(A32="","",IF(Database!G32="","START NOW!",IF(Database!G32<TODAY(),"OVERDUE "&ABS(Database!G32-TODAY())&"d","Today"))) | H32: =IF(G32="✅ DONE", IF(F32="😊 Easy",MIN(Database!D32+2,7), IF(F32="👍 Good",MIN(Database!D32+1,7), IF(F32="😐 Hard",Database!D32, IF(F32="🔴 Again",MAX(Database!D32-1,0), "")))), "") | I32: =IF(G32="✅ DONE",TEXT(TODAY(),"DD/MM/YY"),"")
A33: =IF(AND(Database!A33<>"",OR(Database!G33<=TODAY(),Database!E33="")),33,"") | B33: =IF(A33="","",Database!A33&" - "&Database!B33) | C33: =IF(A33="","","Level "&Database!D33) | D33: =IF(A33="","",IF(Database!E33="","Never",TEXT(Database!E33,"DD/MM/YY"))) | E33: =IF(A33="","",IF(Database!G33="","START NOW!",IF(Database!G33<TODAY(),"OVERDUE "&ABS(Database!G33-TODAY())&"d","Today"))) | H33: =IF(G33="✅ DONE", IF(F33="😊 Easy",MIN(Database!D33+2,7), IF(F33="👍 Good",MIN(Database!D33+1,7), IF(F33="😐 Hard",Database!D33, IF(F33="🔴 Again",MAX(Database!D33-1,0), "")))), "") | I33: =IF(G33="✅ DONE",TEXT(TODAY(),"DD/MM/YY"),"")
A34: =IF(AND(Database!A34<>"",OR(Database!G34<=TODAY(),Database!E34="")),34,"") | B34: =IF(A34="","",Database!A34&" - "&Database!B34) | C34: =IF(A34="","","Level "&Database!D34) | D34: =IF(A34="","",IF(Database!E34="","Never",TEXT(Database!E34,"DD/MM/YY"))) | E34: =IF(A34="","",IF(Database!G34="","START NOW!",IF(Database!G34<TODAY(),"OVERDUE "&ABS(Database!G34-TODAY())&"d","Today"))) | H34: =IF(G34="✅ DONE", IF(F34="😊 Easy",MIN(Database!D34+2,7), IF(F34="👍 Good",MIN(Database!D34+1,7), IF(F34="😐 Hard",Database!D34, IF(F34="🔴 Again",MAX(Database!D34-1,0), "")))), "") | I34: =IF(G34="✅ DONE",TEXT(TODAY(),"DD/MM/YY"),"")
A35: =IF(AND(Database!A35<>"",OR(Database!G35<=TODAY(),Database!E35="")),35,"") | B35: =IF(A35="","",Database!A35&" - "&Database!B35) | C35: =IF(A35="","","Level "&Database!D35) | D35: =IF(A35="","",IF(Database!E35="","Never",TEXT(Database!E35,"DD/MM/YY"))) | E35: =IF(A35="","",IF(Database!G35="","START NOW!",IF(Database!G35<TODAY(),"OVERDUE "&ABS(Database!G35-TODAY())&"d","Today"))) | H35: =IF(G35="✅ DONE", IF(F35="😊 Easy",MIN(Database!D35+2,7), IF(F35="👍 Good",MIN(Database!D35+1,7), IF(F35="😐 Hard",Database!D35, IF(F35="🔴 Again",MAX(Database!D35-1,0), "")))), "") | I35: =IF(G35="✅ DONE",TEXT(TODAY(),"DD/MM/YY"),"")
A36: =IF(AND(Database!A36<>"",OR(Database!G36<=TODAY(),Database!E36="")),36,"") | B36: =IF(A36="","",Database!A36&" - "&Database!B36) | C36: =IF(A36="","","Level "&Database!D36) | D36: =IF(A36="","",IF(Database!E36="","Never",TEXT(Database!E36,"DD/MM/YY"))) | E36: =IF(A36="","",IF(Database!G36="","START NOW!",IF(Database!G36<TODAY(),"OVERDUE "&ABS(Database!G36-TODAY())&"d","Today"))) | H36: =IF(G36="✅ DONE", IF(F36="😊 Easy",MIN(Database!D36+2,7), IF(F36="👍 Good",MIN(Database!D36+1,7), IF(F36="😐 Hard",Database!D36, IF(F36="🔴 Again",MAX(Database!D36-1,0), "")))), "") | I36: =IF(G36="✅ DONE",TEXT(TODAY(),"DD/MM/YY"),"")
A37: =IF(AND(Database!A37<>"",OR(Database!G37<=TODAY(),Database!E37="")),37,"") | B37: =IF(A37="","",Database!A37&" - "&Database!B37) | C37: =IF(A37="","","Level "&Database!D37) | D37: =IF(A37="","",IF(Database!E37="","Never",TEXT(Database!E37,"DD/MM/YY"))) | E37: =IF(A37="","",IF(Database!G37="","START NOW!",IF(Database!G37<TODAY(),"OVERDUE "&ABS(Database!G37-TODAY())&"d","Today"))) | H37: =IF(G37="✅ DONE", IF(F37="😊 Easy",MIN(Database!D37+2,7), IF(F37="👍 Good",MIN(Database!D37+1,7), IF(F37="😐 Hard",Database!D37, IF(F37="🔴 Again",MAX(Database!D37-1,0), "")))), "") | I37: =IF(G37="✅ DONE",TEXT(TODAY(),"DD/MM/YY"),"")
A38: =IF(AND(Database!A38<>"",OR(Database!G38<=TODAY(),Database!E38="")),38,"") | B38: =IF(A38="","",Database!A38&" - "&Database!B38) | C38: =IF(A38="","","Level "&Database!D38) | D38: =IF(A38="","",IF(Database!E38="","Never",TEXT(Database!E38,"DD/MM/YY"))) | E38: =IF(A38="","",IF(Database!G38="","START NOW!",IF(Database!G38<TODAY(),"OVERDUE "&ABS(Database!G38-TODAY())&"d","Today"))) | H38: =IF(G38="✅ DONE", IF(F38="😊 Easy",MIN(Database!D38+2,7), IF(F38="👍 Good",MIN(Database!D38+1,7), IF(F38="😐 Hard",Database!D38, IF(F38="🔴 Again",MAX(Database!D38-1,0), "")))), "") | I38: =IF(G38="✅ DONE",TEXT(TODAY(),"DD/MM/YY"),"")
A39: =IF(AND(Database!A39<>"",OR(Database!G39<=TODAY(),Database!E39="")),39,"") | B39: =IF(A39="","",Database!A39&" - "&Database!B39) | C39: =IF(A39="","","Level "&Database!D39) | D39: =IF(A39="","",IF(Database!E39="","Never",TEXT(Database!E39,"DD/MM/YY"))) | E39: =IF(A39="","",IF(Database!G39="","START NOW!",IF(Database!G39<TODAY(),"OVERDUE "&ABS(Database!G39-TODAY())&"d","Today"))) | H39: =IF(G39="✅ DONE", IF(F39="😊 Easy",MIN(Database!D39+2,7), IF(F39="👍 Good",MIN(Database!D39+1,7), IF(F39="😐 Hard",Database!D39, IF(F39="🔴 Again",MAX(Database!D39-1,0), "")))), "") | I39: =IF(G39="✅ DONE",TEXT(TODAY(),"DD/MM/YY"),"")
A40: =IF(AND(Database!A40<>"",OR(Database!G40<=TODAY(),Database!E40="")),40,"") | B40: =IF(A40="","",Database!A40&" - "&Database!B40) | C40: =IF(A40="","","Level "&Database!D40) | D40: =IF(A40="","",IF(Database!E40="","Never",TEXT(Database!E40,"DD/MM/YY"))) | E40: =IF(A40="","",IF(Database!G40="","START NOW!",IF(Database!G40<TODAY(),"OVERDUE "&ABS(Database!G40-TODAY())&"d","Today"))) | H40: =IF(G40="✅ DONE", IF(F40="😊 Easy",MIN(Database!D40+2,7), IF(F40="👍 Good",MIN(Database!D40+1,7), IF(F40="😐 Hard",Database!D40, IF(F40="🔴 Again",MAX(Database!D40-1,0), "")))), "") | I40: =IF(G40="✅ DONE",TEXT(TODAY(),"DD/MM/YY"),"")
...

Sheet Database
A1: DATABASE - Your Lessons
A2: ✅ Update col D (Level) and col E (Last Review) with green values from TODAY sheet after completing reviews!
A3: Topic | B3: Lesson | C3: Difficulty | D3: Level | E3: Last Review | F3: Interval | G3: Next Review
A4: Anatomy | B4: Heart chambers | C4: Normal | D4: 2 | E4: 46054 | F4: =IF(D4="","", ROUND( CHOOSE(MIN(D4+1,8),0,1,3,7,15,30,60,90) * IF(C4="Easy Topic",1.3,IF(C4="Hard Topic",0.7,1)) ,0)) -> 3 | G4: =IF(E4="","",MAX(E4,TODAY())+F4) -> 46066
A5: Microbio | B5: Viral replication | C5: Hard Topic | D5: 0 | F5: =IF(D5="","", ROUND( CHOOSE(MIN(D5+1,8),0,1,3,7,15,30,60,90) * IF(C5="Easy Topic",1.3,IF(C5="Hard Topic",0.7,1)) ,0)) -> 0 | G5: =IF(E5="","",MAX(E5,TODAY())+F5)
A6: Pharmacology | B6: Benzodiazepines | C6: Easy Topic | D6: 1 | E6: 46062 | F6: =IF(D6="","", ROUND( CHOOSE(MIN(D6+1,8),0,1,3,7,15,30,60,90) * IF(C6="Easy Topic",1.3,IF(C6="Hard Topic",0.7,1)) ,0)) -> 1 | G6: =IF(E6="","",MAX(E6,TODAY())+F6) -> 46064
A7: Physiology | B7: Cardiac cycle | C7: Normal | D7: 3 | E7: 46050 | F7: =IF(D7="","", ROUND( CHOOSE(MIN(D7+1,8),0,1,3,7,15,30,60,90) * IF(C7="Easy Topic",1.3,IF(C7="Hard Topic",0.7,1)) ,0)) -> 7 | G7: =IF(E7="","",MAX(E7,TODAY())+F7) -> 46070
F8: =IF(D8="","", ROUND( CHOOSE(MIN(D8+1,8),0,1,3,7,15,30,60,90) * IF(C8="Easy Topic",1.3,IF(C8="Hard Topic",0.7,1)) ,0)) | G8: =IF(E8="","",MAX(E8,TODAY())+F8)
F9: =IF(D9="","", ROUND( CHOOSE(MIN(D9+1,8),0,1,3,7,15,30,60,90) * IF(C9="Easy Topic",1.3,IF(C9="Hard Topic",0.7,1)) ,0)) | G9: =IF(E9="","",MAX(E9,TODAY())+F9)
F10: =IF(D10="","", ROUND( CHOOSE(MIN(D10+1,8),0,1,3,7,15,30,60,90) * IF(C10="Easy Topic",1.3,IF(C10="Hard Topic",0.7,1)) ,0)) | G10: =IF(E10="","",MAX(E10,TODAY())+F10)
F11: =IF(D11="","", ROUND( CHOOSE(MIN(D11+1,8),0,1,3,7,15,30,60,90) * IF(C11="Easy Topic",1.3,IF(C11="Hard Topic",0.7,1)) ,0)) | G11: =IF(E11="","",MAX(E11,TODAY())+F11)
F12: =IF(D12="","", ROUND( CHOOSE(MIN(D12+1,8),0,1,3,7,15,30,60,90) * IF(C12="Easy Topic",1.3,IF(C12="Hard Topic",0.7,1)) ,0)) | G12: =IF(E12="","",MAX(E12,TODAY())+F12)
F13: =IF(D13="","", ROUND( CHOOSE(MIN(D13+1,8),0,1,3,7,15,30,60,90) * IF(C13="Easy Topic",1.3,IF(C13="Hard Topic",0.7,1)) ,0)) | G13: =IF(E13="","",MAX(E13,TODAY())+F13)
F14: =IF(D14="","", ROUND( CHOOSE(MIN(D14+1,8),0,1,3,7,15,30,60,90) * IF(C14="Easy Topic",1.3,IF(C14="Hard Topic",0.7,1)) ,0)) | G14: =IF(E14="","",MAX(E14,TODAY())+F14)
F15: =IF(D15="","", ROUND( CHOOSE(MIN(D15+1,8),0,1,3,7,15,30,60,90) * IF(C15="Easy Topic",1.3,IF(C15="Hard Topic",0.7,1)) ,0)) | G15: =IF(E15="","",MAX(E15,TODAY())+F15)
F16: =IF(D16="","", ROUND( CHOOSE(MIN(D16+1,8),0,1,3,7,15,30,60,90) * IF(C16="Easy Topic",1.3,IF(C16="Hard Topic",0.7,1)) ,0)) | G16: =IF(E16="","",MAX(E16,TODAY())+F16)
F17: =IF(D17="","", ROUND( CHOOSE(MIN(D17+1,8),0,1,3,7,15,30,60,90) * IF(C17="Easy Topic",1.3,IF(C17="Hard Topic",0.7,1)) ,0)) | G17: =IF(E17="","",MAX(E17,TODAY())+F17)
F18: =IF(D18="","", ROUND( CHOOSE(MIN(D18+1,8),0,1,3,7,15,30,60,90) * IF(C18="Easy Topic",1.3,IF(C18="Hard Topic",0.7,1)) ,0)) | G18: =IF(E18="","",MAX(E18,TODAY())+F18)
F19: =IF(D19="","", ROUND( CHOOSE(MIN(D19+1,8),0,1,3,7,15,30,60,90) * IF(C19="Easy Topic",1.3,IF(C19="Hard Topic",0.7,1)) ,0)) | G19: =IF(E19="","",MAX(E19,TODAY())+F19)
... F203: =IF(D203="","", ROUND( CHOOSE(MIN(D203+1,8),0,1,3,7,15,30,60,90) * IF(C203="Easy Topic",1.3,IF(C203="Hard Topic",0.7,1)) ,0)) | G203: =IF(E203="","",MAX(E203,TODAY())+F203)

Sheet 📊 Stats
A1: 📊 YOUR PROGRESS
A3: 📚 STATUS
A4: Due Now: | B4: =COUNTIFS(Database!$G:$G,"<="&TODAY(),Database!$A:$A,"<>")+(COUNTIF(Database!$E:$E,"")-COUNTBLANK(Database!$A:$A)) -> 3
A5: Total Lessons: | B5: =COUNTA(Database!$A:$A)-3 -> 4
A6: Level 7: | B6: =COUNTIF(Database!$D:$D,7) -> 0
