Workbook

Sheet 📖 Review Tracker
A1: REVIEW TRACKER - Add Your Lessons Here
A2: HOW TO USE: 1) Enter lesson details (columns A-D) 2) Enter first study date in column E 3) As you complete reviews, enter dates in columns F-L
A3: Category | B3: Sub-category | C3: Lesson Name | D3: Notes | E3: J0 (First) | F3: J1 (+1d) | G3: J3 (+3d) | H3: J7 (+7d) | I3: J15 (+15d) | J3: J30 (+30d) | K3: J60 (+60d) | L3: J90 (+90d) | M3: Next Review | N3: Days Until | O3: Status
A4: Anatomy | B4: Cardiology | C4: Heart structure | D4: Chambers & valves | E4: 46037 | F4: 46038 | G4: 46041 | H4: =IF(OR(E4="",G4=""),"",MAX(E4,F4,G4)+7) -> 46048 | I4: =IF(OR(E4="",H4=""),"",MAX(E4,F4,G4,H4)+15) -> 46063 | J4: =IF(OR(E4="",I4=""),"",MAX(E4,F4,G4,H4,I4)+30) -> 46093 | K4: =IF(OR(E4="",J4=""),"",MAX(E4,F4,G4,H4,I4,J4)+60) -> 46153 | L4: =IF(OR(E4="",K4=""),"",MAX(E4,F4,G4,H4,I4,J4,K4)+90) -> 46243 | M4: =IF(E4="","",IF(F4="",F4,IF(G4="",G4,IF(H4="",H4,IF(I4="",I4,IF(J4="",J4,IF(K4="",K4,IF(L4="",L4,"DONE")))))))) -> DONE | N4: =IF(OR(E4="",M4="DONE"),"",M4-TODAY()) | O4: =IF(E4="","",IF(M4="DONE","✅ Complete",IF(N4<0,"🔴 OVERDUE",IF(N4=0,"🟡 TODAY",IF(N4<=3,"🟠 SOON","🟢 Later"))))) -> ✅ Complete
A5: Microbiology | B5: Virology | C5: Viral replication | D5: DNA vs RNA | E5: 46042 | F5: =IF(E5="","",E5+1) -> 46043 | G5: =IF(OR(E5="",F5=""),"",MAX(E5,F5)+3) -> 46046 | H5: =IF(OR(E5="",G5=""),"",MAX(E5,F5,G5)+7) -> 46053 | I5: =IF(OR(E5="",H5=""),"",MAX(E5,F5,G5,H5)+15) -> 46068 | J5: =IF(OR(E5="",I5=""),"",MAX(E5,F5,G5,H5,I5)+30) -> 46098 | K5: =IF(OR(E5="",J5=""),"",MAX(E5,F5,G5,H5,I5,J5)+60) -> 46158 | L5: =IF(OR(E5="",K5=""),"",MAX(E5,F5,G5,H5,I5,J5,K5)+90) -> 46248 | M5: =IF(E5="","",IF(F5="",F5,IF(G5="",G5,IF(H5="",H5,IF(I5="",I5,IF(J5="",J5,IF(K5="",K5,IF(L5="",L5,"DONE")))))))) -> DONE | N5: =IF(OR(E5="",M5="DONE"),"",M5-TODAY()) | O5: =IF(E5="","",IF(M5="DONE","✅ Complete",IF(N5<0,"🔴 OVERDUE",IF(N5=0,"🟡 TODAY",IF(N5<=3,"🟠 SOON","🟢 Later"))))) -> ✅ Complete
A6: Pharmacology | B6: CNS | C6: Benzodiazepines | D6: GABA mechanism | E6: 46054 | F6: =IF(E6="","",E6+1) -> 46055 | G6: =IF(OR(E6="",F6=""),"",MAX(E6,F6)+3) -> 46058 | H6: =IF(OR(E6="",G6=""),"",MAX(E6,F6,G6)+7) -> 46065 | I6: =IF(OR(E6="",H6=""),"",MAX(E6,F6,G6,H6)+15) -> 46080 | J6: =IF(OR(E6="",I6=""),"",MAX(E6,F6,G6,H6,I6)+30) -> 46110 | K6: =IF(OR(E6="",J6=""),"",MAX(E6,F6,G6,H6,I6,J6)+60) -> 46170 | L6: =IF(OR(E6="",K6=""),"",MAX(E6,F6,G6,H6,I6,J6,K6)+90) -> 46260 | M6: =IF(E6="","",IF(F6="",F6,IF(G6="",G6,IF(H6="",H6,IF(I6="",I6,IF(J6="",J6,IF(K6="",K6,IF(L6="",L6,"DONE")))))))) -> DONE | N6: =IF(OR(E6="",M6="DONE"),"",M6-TODAY()) | O6: =IF(E6="","",IF(M6="DONE","✅ Complete",IF(N6<0,"🔴 OVERDUE",IF(N6=0,"🟡 TODAY",IF(N6<=3,"🟠 SOON","🟢 Later"))))) -> ✅ Complete
F7: =IF(E7="","",E7+1) | G7: =IF(OR(E7="",F7=""),"",MAX(E7,F7)+3) | H7: =IF(OR(E7="",G7=""),"",MAX(E7,F7,G7)+7) | I7: =IF(OR(E7="",H7=""),"",MAX(E7,F7,G7,H7)+15) | J7: =IF(OR(E7="",I7=""),"",MAX(E7,F7,G7,H7,I7)+30) | K7: =IF(OR(E7="",J7=""),"",MAX(E7,F7,G7,H7,I7,J7)+60) | L7: =IF(OR(E7="",K7=""),"",MAX(E7,F7,G7,H7,I7,J7,K7)+90) | M7: =IF(E7="","",IF(F7="",F7,IF(G7="",G7,IF(H7="",H7,IF(I7="",I7,IF(J7="",J7,IF(K7="",K7,IF(L7="",L7,"DONE")))))))) | N7: =IF(OR(E7="",M7="DONE"),"",M7-TODAY()) | O7: =IF(E7="","",IF(M7="DONE","✅ Complete",IF(N7<0,"🔴 OVERDUE",IF(N7=0,"🟡 TODAY",IF(N7<=3,"🟠 SOON","🟢 Later")))))
F8: =IF(E8="","",E8+1) | G8: =IF(OR(E8="",F8=""),"",MAX(E8,F8)+3) | H8: =IF(OR(E8="",G8=""),"",MAX(E8,F8,G8)+7) | I8: =IF(OR(E8="",H8=""),"",MAX(E8,F8,G8,H8)+15) | J8: =IF(OR(E8="",I8=""),"",MAX(E8,F8,G8,H8,I8)+30) | K8: =IF(OR(E8="",J8=""),"",MAX(E8,F8,G8,H8,I8,J8)+60) | L8: =IF(OR(E8="",K8=""),"",MAX(E8,F8,G8,H8,I8,J8,K8)+90) | M8: =IF(E8="","",IF(F8="",F8,IF(G8="",G8,IF(H8="",H8,IF(I8="",I8,IF(J8="",J8,IF(K8="",K8,IF(L8="",L8,"DONE")))))))) | N8: =IF(OR(E8="",M8="DONE"),"",M8-TODAY()) | O8: =IF(E8="","",IF(M8="DONE","✅ Complete",IF(N8<0,"🔴 OVERDUE",IF(N8=0,"🟡 TODAY",IF(N8<=3,"🟠 SOON","🟢 Later")))))
F9: =IF(E9="","",E9+1) | G9: =IF(OR(E9="",F9=""),"",MAX(E9,F9)+3) | H9: =IF(OR(E9="",G9=""),"",MAX(E9,F9,G9)+7) | I9: =IF(OR(E9="",H9=""),"",MAX(E9,F9,G9,H9)+15) | J9: =IF(OR(E9="",I9=""),"",MAX(E9,F9,G9,H9,I9)+30) | K9: =IF(OR(E9="",J9=""),"",MAX(E9,F9,G9,H9,I9,J9)+60) | L9: =IF(OR(E9="",K9=""),"",MAX(E9,F9,G9,H9,I9,J9,K9)+90) | M9: =IF(E9="","",IF(F9="",F9,IF(G9="",G9,IF(H9="",H9,IF(I9="",I9,IF(J9="",J9,IF(K9="",K9,IF(L9="",L9,"DONE")))))))) | N9: =IF(OR(E9="",M9="DONE"),"",M9-TODAY()) | O9: =IF(E9="","",IF(M9="DONE","✅ Complete",IF(N9<0,"🔴 OVERDUE",IF(N9=0,"🟡 TODAY",IF(N9<=3,"🟠 SOON","🟢 Later")))))
F10: =IF(E10="","",E10+1) | G10: =IF(OR(E10="",F10=""),"",MAX(E10,F10)+3) | H10: =IF(OR(E10="",G10=""),"",MAX(E10,F10,G10)+7) | I10: =IF(OR(E10="",H10=""),"",MAX(E10,F10,G10,H10)+15) | J10: =IF(OR(E10="",I10=""),"",MAX(E10,F10,G10,H10,I10)+30) | K10: =IF(OR(E10="",J10=""),"",MAX(E10,F10,G10,H10,I10,J10)+60) | L10: =IF(OR(E10="",K10=""),"",MAX(E10,F10,G10,H10,I10,J10,K10)+90) | M10: =IF(E10="","",IF(F10="",F10,IF(G10="",G10,IF(H10="",H10,IF(I10="",I10,IF(J10="",J10,IF(K10="",K10,IF(L10="",L10,"DONE")))))))) | N10: =IF(OR(E10="",M10="DONE"),"",M10-TODAY()) | O10: =IF(E10="","",IF(M10="DONE","✅ Complete",IF(N10<0,"🔴 OVERDUE",IF(N10=0,"🟡 TODAY",IF(N10<=3,"🟠 SOON","🟢 Later")))))
F11: =IF(E11="","",E11+1) | G11: =IF(OR(E11="",F11=""),"",MAX(E11,F11)+3) | H11: =IF(OR(E11="",G11=""),"",MAX(E11,F11,G11)+7) | I11: =IF(OR(E11="",H11=""),"",MAX(E11,F11,G11,H11)+15) | J11: =IF(OR(E11="",I11=""),"",MAX(E11,F11,G11,H11,I11)+30) | K11: =IF(OR(E11="",J11=""),"",MAX(E11,F11,G11,H11,I11,J11)+60) | L11: =IF(OR(E11="",K11=""),"",MAX(E11,F11,G11,H11,I11,J11,K11)+90) | M11: =IF(E11="","",IF(F11="",F11,IF(G11="",G11,IF(H11="",H11,IF(I11="",I11,IF(J11="",J11,IF(K11="",K11,IF(L11="",L11,"DONE")))))))) | N11: =IF(OR(E11="",M11="DONE"),"",M11-TODAY()) | O11: =IF(E11="","",IF(M11="DONE","✅ Complete",IF(N11<0,"🔴 OVERDUE",IF(N11=0,"🟡 TODAY",IF(N11<=3,"🟠 SOON","🟢 Later")))))
F12: =IF(E12="","",E12+1) | G12: =IF(OR(E12="",F12=""),"",MAX(E12,F12)+3) | H12: =IF(OR(E12="",G12=""),"",MAX(E12,F12,G12)+7) | I12: =IF(OR(E12="",H12=""),"",MAX(E12,F12,G12,H12)+15) | J12: =IF(OR(E12="",I12=""),"",MAX(E12,F12,G12,H12,I12)+30) | K12: =IF(OR(E12="",J12=""),"",MAX(E12,F12,G12,H12,I12,J12)+60) | L12: =IF(OR(E12="",K12=""),"",MAX(E12,F12,G12,H12,I12,J12,K12)+90) | M12: =IF(E12="","",IF(F12="",F12,IF(G12="",G12,IF(H12="",H12,IF(I12="",I12,IF(J12="",J12,IF(K12="",K12,IF(L12="",L12,"DONE")))))))) | N12: =IF(OR(E12="",M12="DONE"),"",M12-TODAY()) | O12: =IF(E12="","",IF(M12="DONE","✅ Complete",IF(N12<0,"🔴 OVERDUE",IF(N12=0,"🟡 TODAY",IF(N12<=3,"🟠 SOON","🟢 Later")))))
F13: =IF(E13="","",E13+1) | G13: =IF(OR(E13="",F13=""),"",MAX(E13,F13)+3) | H13: =IF(OR(E13="",G13=""),"",MAX(E13,F13,G13)+7) | I13: =IF(OR(E13="",H13=""),"",MAX(E13,F13,G13,H13)+15) | J13: =IF(OR(E13="",I13=""),"",MAX(E13,F13,G13,H13,I13)+30) | K13: =IF(OR(E13="",J13=""),"",MAX(E13,F13,G13,H13,I13,J13)+60) | L13: =IF(OR(E13="",K13=""),"",MAX(E13,F13,G13,H13,I13,J13,K13)+90) | M13: =IF(E13="","",IF(F13="",F13,IF(G13="",G13,IF(H13="",H13,IF(I13="",I13,IF(J13="",J13,IF(K13="",K13,IF(L13="",L13,"DONE")))))))) | N13: =IF(OR(E13="",M13="DONE"),"",M13-TODAY()) | O13: =IF(E13="","",IF(M13="DONE","✅ Complete",IF(N13<0,"🔴 OVERDUE",IF(N13=0,"🟡 TODAY",IF(N13<=3,"🟠 SOON","🟢 Later")))))
F14: =IF(E14="","",E14+1) | G14: =IF(OR(E14="",F14=""),"",MAX(E14,F14)+3) | H14: =IF(OR(E14="",G14=""),"",MAX(E14,F14,G14)+7) | I14: =IF(OR(E14="",H14=""),"",MAX(E14,F14,G14,H14)+15) | J14: =IF(OR(E14="",I14=""),"",MAX(E14,F14,G14,H14,I14)+30) | K14: =IF(OR(E14="",J14=""),"",MAX(E14,F14,G14,H14,I14,J14)+60) | L14: =IF(OR(E14="",K14=""),"",MAX(E14,F14,G14,H14,I14,J14,K14)+90) | M14: =IF(E14="","",IF(F14="",F14,IF(G14="",G14,IF(H14="",H14,IF(I14="",I14,IF(J14="",J14,IF(K14="",K14,IF(L14="",L14,"DONE")))))))) | N14: =IF(OR(E14="",M14="DONE"),"",M14-TODAY()) | O14: =IF(E14="","",IF(M14="DONE","✅ Complete",IF(N14<0,"🔴 OVERDUE",IF(N14=0,"🟡 TODAY",IF(N14<=3,"🟠 SOON","🟢 Later")))))
F15: =IF(E15="","",E15+1) | G15: =IF(OR(E15="",F15=""),"",MAX(E15,F15)+3) | H15: =IF(OR(E15="",G15=""),"",MAX(E15,F15,G15)+7) | I15: =IF(OR(E15="",H15=""),"",MAX(E15,F15,G15,H15)+15) | J15: =IF(OR(E15="",I15=""),"",MAX(E15,F15,G15,H15,I15)+30) | K15: =IF(OR(E15="",J15=""),"",MAX(E15,F15,G15,H15,I15,J15)+60) | L15: =IF(OR(E15="",K15=""),"",MAX(E15,F15,G15,H15,I15,J15,K15)+90) | M15: =IF(E15="","",IF(F15="",F15,IF(G15="",G15,IF(H15="",H15,IF(I15="",I15,IF(J15="",J15,IF(K15="",K15,IF(L15="",L15,"DONE")))))))) | N15: =IF(OR(E15="",M15="DONE"),"",M15-TODAY()) | O15: =IF(E15="","",IF(M15="DONE","✅ Complete",IF(N15<0,"🔴 OVERDUE",IF(N15=0,"🟡 TODAY",IF(N15<=3,"🟠 SOON","🟢 Later")))))
F16: =IF(E16="","",E16+1) | G16: =IF(OR(E16="",F16=""),"",MAX(E16,F16)+3) | H16: =IF(OR(E16="",G16=""),"",MAX(E16,F16,G16)+7) | I16: =IF(OR(E16="",H16=""),"",MAX(E16,F16,G16,H16)+15) | J16: =IF(OR(E16="",I16=""),"",MAX(E16,F16,G16,H16,I16)+30) | K16: =IF(OR(E16="",J16=""),"",MAX(E16,F16,G16,H16,I16,J16)+60) | L16: =IF(OR(E16="",K16=""),"",MAX(E16,F16,G16,H16,I16,J16,K16)+90) | M16: =IF(E16="","",IF(F16="",F16,IF(G16="",G16,IF(H16="",H16,IF(I16="",I16,IF(J16="",J16,IF(K16="",K16,IF(L16="",L16,"DONE")))))))) | N16: =IF(OR(E16="",M16="DONE"),"",M16-TODAY()) | O16: =IF(E16="","",IF(M16="DONE","✅ Complete",IF(N16<0,"🔴 OVERDUE",IF(N16=0,"🟡 TODAY",IF(N16<=3,"🟠 SOON","🟢 Later")))))
F17: =IF(E17="","",E17+1) | G17: =IF(OR(E17="",F17=""),"",MAX(E17,F17)+3) | H17: =IF(OR(E17="",G17=""),"",MAX(E17,F17,G17)+7) | I17: =IF(OR(E17="",H17=""),"",MAX(E17,F17,G17,H17)+15) | J17: =IF(OR(E17="",I17=""),"",MAX(E17,F17,G17,H17,I17)+30) | K17: =IF(OR(E17="",J17=""),"",MAX(E17,F17,G17,H17,I17,J17)+60) | L17: =IF(OR(E17="",K17=""),"",MAX(E17,F17,G17,H17,I17,J17,K17)+90) | M17: =IF(E17="","",IF(F17="",F17,IF(G17="",G17,IF(H17="",H17,IF(I17="",I17,IF(J17="",J17,IF(K17="",K17,IF(L17="",L17,"DONE")))))))) | N17: =IF(OR(E17="",M17="DONE"),"",M17-TODAY()) | O17: =IF(E17="","",IF(M17="DONE","✅ Complete",IF(N17<0,"🔴 OVERDUE",IF(N17=0,"🟡 TODAY",IF(N17<=3,"🟠 SOON","🟢 Later")))))
F18: =IF(E18="","",E18+1) | G18: =IF(OR(E18="",F18=""),"",MAX(E18,F18)+3) | H18: =IF(OR(E18="",G18=""),"",MAX(E18,F18,G18)+7) | I18: =IF(OR(E18="",H18=""),"",MAX(E18,F18,G18,H18)+15) | J18: =IF(OR(E18="",I18=""),"",MAX(E18,F18,G18,H18,I18)+30) | K18: =IF(OR(E18="",J18=""),"",MAX(E18,F18,G18,H18,I18,J18)+60) | L18: =IF(OR(E18="",K18=""),"",MAX(E18,F18,G18,H18,I18,J18,K18)+90) | M18: =IF(E18="","",IF(F18="",F18,IF(G18="",G18,IF(H18="",H18,IF(I18="",I18,IF(J18="",J18,IF(K18="",K18,IF(L18="",L18,"DONE")))))))) | N18: =IF(OR(E18="",M18="DONE"),"",M18-TODAY()) | O18: =IF(E18="","",IF(M18="DONE","✅ Complete",IF(N18<0,"🔴 OVERDUE",IF(N18=0,"🟡 TODAY",IF(N18<=3,"🟠 SOON","🟢 Later")))))
... F199: =IF(E199="","",E199+1) | G199: =IF(OR(E199="",F199=""),"",MAX(E199,F199)+3) | H199: =IF(OR(E199="",G199=""),"",MAX(E199,F199,G199)+7) | I199: =IF(OR(E199="",H199=""),"",MAX(E199,F199,G199,H199)+15) | J199: =IF(OR(E199="",I199=""),"",MAX(E199,F199,G199,H199,I199)+30) | K199: =IF(OR(E199="",J199=""),"",MAX(E199,F199,G199,H199,I199,J199)+60) | L199: =IF(OR(E199="",K199=""),"",MAX(E199,F199,G199,H199,I199,J199,K199)+90) | M199: =IF(E199="","",IF(F199="",F199,IF(G199="",G199,IF(H199="",H199,IF(I199="",I199,IF(J199="",J199,IF(K199="",K199,IF(L199="",L199,"DONE")))))))) | N199: =IF(OR(E199="",M199="DONE"),"",M199-TODAY()) | O199: =IF(E199="","",IF(M199="DONE","✅ Complete",IF(N199<0,"🔴 OVERDUE",IF(N199=0,"🟡 TODAY",IF(N199<=3,"🟠 SOON","🟢 Later")))))

Sheet 📚 To Study Today
A1: 📚 LESSONS TO STUDY TODAY
A2: Today: | B2: =TEXT(TODAY(),"DD/MM/YYYY") -> 09/02/2026 | D2: Due/Overdue Count: | E2: =COUNTIFS('📖 Review Tracker'!$O:$O,"🔴 OVERDUE")+COUNTIFS('📖 Review Tracker'!$O:$O,"🟡 TODAY") -> 0
A3: ✏️ Mark lessons as "✅ Done" in column I, then COPY the date from column H and PASTE it into the correct review column in the Review Tracker sheet
A4: # | B4: Category | C4: Lesson | D4: Scheduled | E4: Days Late | F4: Review Type | G4: Priority | H4: Enter Date | I4: Mark Done
A5: =IF('📖 Review Tracker'!$C4="","",IF(OR('📖 Review Tracker'!$O4="🔴 OVERDUE",'📖 Review Tracker'!$O4="🟡 TODAY"),4,"")) | B5: =IF('📖 Review Tracker'!$C4="","",IF(OR('📖 Review Tracker'!$O4="🔴 OVERDUE",'📖 Review Tracker'!$O4="🟡 TODAY"),'📖 Review Tracker'!$A4,"")) | C5: =IF('📖 Review Tracker'!$C4="","",IF(OR('📖 Review Tracker'!$O4="🔴 OVERDUE",'📖 Review Tracker'!$O4="🟡 TODAY"),'📖 Review Tracker'!$C4,"")) | D5: =IF('📖 Review Tracker'!$C4="","",IF(OR('📖 Review Tracker'!$O4="🔴 OVERDUE",'📖 Review Tracker'!$O4="🟡 TODAY"),TEXT('📖 Review Tracker'!$M4,"DD/MM/YYYY"),"")) | E5: =IF('📖 Review Tracker'!$C4="","",IF(OR('📖 Review Tracker'!$O4="🔴 OVERDUE",'📖 Review Tracker'!$O4="🟡 TODAY"),'📖 Review Tracker'!$N4,"")) | F5: =IF('📖 Review Tracker'!$C4="","",IF(OR('📖 Review Tracker'!$O4="🔴 OVERDUE",'📖 Review Tracker'!$O4="🟡 TODAY"),IF('📖 Review Tracker'!$F4="","J1",IF('📖 Review Tracker'!$G4="","J3",IF('📖 Review Tracker'!$H4="","J7",IF('📖 Review Tracker'!$I4="","J15",IF('📖 Review Tracker'!$J4="","J30",IF('📖 Review Tracker'!$K4="","J60","J90")))))),"")) | G5: =IF('📖 Review Tracker'!$C4="","",IF(OR('📖 Review Tracker'!$O4="🔴 OVERDUE",'📖 Review Tracker'!$O4="🟡 TODAY"),'📖 Review Tracker'!$O4,"")) | H5: =IF(I5="✅ Done",TEXT(TODAY(),"DD/MM/YYYY"),"")
A6: =IF('📖 Review Tracker'!$C5="","",IF(OR('📖 Review Tracker'!$O5="🔴 OVERDUE",'📖 Review Tracker'!$O5="🟡 TODAY"),5,"")) | B6: =IF('📖 Review Tracker'!$C5="","",IF(OR('📖 Review Tracker'!$O5="🔴 OVERDUE",'📖 Review Tracker'!$O5="🟡 TODAY"),'📖 Review Tracker'!$A5,"")) | C6: =IF('📖 Review Tracker'!$C5="","",IF(OR('📖 Review Tracker'!$O5="🔴 OVERDUE",'📖 Review Tracker'!$O5="🟡 TODAY"),'📖 Review Tracker'!$C5,"")) | D6: =IF('📖 Review Tracker'!$C5="","",IF(OR('📖 Review Tracker'!$O5="🔴 OVERDUE",'📖 Review Tracker'!$O5="🟡 TODAY"),TEXT('📖 Review Tracker'!$M5,"DD/MM/YYYY"),"")) | E6: =IF('📖 Review Tracker'!$C5="","",IF(OR('📖 Review Tracker'!$O5="🔴 OVERDUE",'📖 Review Tracker'!$O5="🟡 TODAY"),'📖 Review Tracker'!$N5,"")) | F6: =IF('📖 Review Tracker'!$C5="","",IF(OR('📖 Review Tracker'!$O5="🔴 OVERDUE",'📖 Review Tracker'!$O5="🟡 TODAY"),IF('📖 Review Tracker'!$F5="","J1",IF('📖 Review Tracker'!$G5="","J3",IF('📖 Review Tracker'!$H5="","J7",IF('📖 Review Tracker'!$I5="","J15",IF('📖 Review Tracker'!$J5="","J30",IF('📖 Review Tracker'!$K5="","J60","J90")))))),"")) | G6: =IF('📖 Review Tracker'!$C5="","",IF(OR('📖 Review Tracker'!$O5="🔴 OVERDUE",'📖 Review Tracker'!$O5="🟡 TODAY"),'📖 Review Tracker'!$O5,"")) | H6: =IF(I6="✅ Done",TEXT(TODAY(),"DD/MM/YYYY"),"")
A7: =IF('📖 Review Tracker'!$C6="","",IF(OR('📖 Review Tracker'!$O6="🔴 OVERDUE",'📖 Review Tracker'!$O6="🟡 TODAY"),6,"")) | B7: =IF('📖 Review Tracker'!$C6="","",IF(OR('📖 Review Tracker'!$O6="🔴 OVERDUE",'📖 Review Tracker'!$O6="🟡 TODAY"),'📖 Review Tracker'!$A6,"")) | C7: =IF('📖 Review Tracker'!$C6="","",IF(OR('📖 Review Tracker'!$O6="🔴 OVERDUE",'📖 Review Tracker'!$O6="🟡 TODAY"),'📖 Review Tracker'!$C6,"")) | D7: =IF('📖 Review Tracker'!$C6="","",IF(OR('📖 Review Tracker'!$O6="🔴 OVERDUE",'📖 Review Tracker'!$O6="🟡 TODAY"),TEXT('📖 Review Tracker'!$M6,"DD/MM/YYYY"),"")) | E7: =IF('📖 Review Tracker'!$C6="","",IF(OR('📖 Review Tracker'!$O6="🔴 OVERDUE",'📖 Review Tracker'!$O6="🟡 TODAY"),'📖 Review Tracker'!$N6,"")) | F7: =IF('📖 Review Tracker'!$C6="","",IF(OR('📖 Review Tracker'!$O6="🔴 OVERDUE",'📖 Review Tracker'!$O6="🟡 TODAY"),IF('📖 Review Tracker'!$F6="","J1",IF('📖 Review Tracker'!$G6="","J3",IF('📖 Review Tracker'!$H6="","J7",IF('📖 Review Tracker'!$I6="","J15",IF('📖 Review Tracker'!$J6="","J30",IF('📖 Review Tracker'!$K6="","J60","J90")))))),"")) | G7: =IF('📖 Review Tracker'!$C6="","",IF(OR('📖 Review Tracker'!$O6="🔴 OVERDUE",'📖 Review Tracker'!$O6="🟡 TODAY"),'📖 Review Tracker'!$O6,"")) | H7: =IF(I7="✅ Done",TEXT(TODAY(),"DD/MM/YYYY"),"")
A8: =IF('📖 Review Tracker'!$C7="","",IF(OR('📖 Review Tracker'!$O7="🔴 OVERDUE",'📖 Review Tracker'!$O7="🟡 TODAY"),7,"")) | B8: =IF('📖 Review Tracker'!$C7="","",IF(OR('📖 Review Tracker'!$O7="🔴 OVERDUE",'📖 Review Tracker'!$O7="🟡 TODAY"),'📖 Review Tracker'!$A7,"")) | C8: =IF('📖 Review Tracker'!$C7="","",IF(OR('📖 Review Tracker'!$O7="🔴 OVERDUE",'📖 Review Tracker'!$O7="🟡 TODAY"),'📖 Review Tracker'!$C7,"")) | D8: =IF('📖 Review Tracker'!$C7="","",IF(OR('📖 Review Tracker'!$O7="🔴 OVERDUE",'📖 Review Tracker'!$O7="🟡 TODAY"),TEXT('📖 Review Tracker'!$M7,"DD/MM/YYYY"),"")) | E8: =IF('📖 Review Tracker'!$C7="","",IF(OR('📖 Review Tracker'!$O7="🔴 OVERDUE",'📖 Review Tracker'!$O7="🟡 TODAY"),'📖 Review Tracker'!$N7,"")) | F8: =IF('📖 Review Tracker'!$C7="","",IF(OR('📖 Review Tracker'!$O7="🔴 OVERDUE",'📖 Review Tracker'!$O7="🟡 TODAY"),IF('📖 Review Tracker'!$F7="","J1",IF('📖 Review Tracker'!$G7="","J3",IF('📖 Review Tracker'!$H7="","J7",IF('📖 Review Tracker'!$I7="","J15",IF('📖 Review Tracker'!$J7="","J30",IF('📖 Review Tracker'!$K7="","J60","J90")))))),"")) | G8: =IF('📖 Review Tracker'!$C7="","",IF(OR('📖 Review Tracker'!$O7="🔴 OVERDUE",'📖 Review Tracker'!$O7="🟡 TODAY"),'📖 Review Tracker'!$O7,"")) | H8: =IF(I8="✅ Done",TEXT(TODAY(),"DD/MM/YYYY"),"")
A9: =IF('📖 Review Tracker'!$C8="","",IF(OR('📖 Review Tracker'!$O8="🔴 OVERDUE",'📖 Review Tracker'!$O8="🟡 TODAY"),8,"")) | B9: =IF('📖 Review Tracker'!$C8="","",IF(OR('📖 Review Tracker'!$O8="🔴 OVERDUE",'📖 Review Tracker'!$O8="🟡 TODAY"),'📖 Review Tracker'!$A8,"")) | C9: =IF('📖 Review Tracker'!$C8="","",IF(OR('📖 Review Tracker'!$O8="🔴 OVERDUE",'📖 Review Tracker'!$O8="🟡 TODAY"),'📖 Review Tracker'!$C8,"")) | D9: =IF('📖 Review Tracker'!$C8="","",IF(OR('📖 Review Tracker'!$O8="🔴 OVERDUE",'📖 Review Tracker'!$O8="🟡 TODAY"),TEXT('📖 Review Tracker'!$M8,"DD/MM/YYYY"),"")) | E9: =IF('📖 Review Tracker'!$C8="","",IF(OR('📖 Review Tracker'!$O8="🔴 OVERDUE",'📖 Review Tracker'!$O8="🟡 TODAY"),'📖 Review Tracker'!$N8,"")) | F9: =IF('📖 Review Tracker'!$C8="","",IF(OR('📖 Review Tracker'!$O8="🔴 OVERDUE",'📖 Review Tracker'!$O8="🟡 TODAY"),IF('📖 Review Tracker'!$F8="","J1",IF('📖 Review Tracker'!$G8="","J3",IF('📖 Review Tracker'!$H8="","J7",IF('📖 Review Tracker'!$I8="","J15",IF('📖 Review Tracker'!$J8="","J30",IF('📖 Review Tracker'!$K8="","J60","J90")))))),"")) | G9: =IF('📖 Review Tracker'!$C8="","",IF(OR('📖 Review Tracker'!$O8="🔴 OVERDUE",'📖 Review Tracker'!$O8="🟡 TODAY"),'📖 Review Tracker'!$O8,"")) | H9: =IF(I9="✅ Done",TEXT(TODAY(),"DD/MM/YYYY"),"")
A10: =IF('📖 Review Tracker'!$C9="","",IF(OR('📖 Review Tracker'!$O9="🔴 OVERDUE",'📖 Review Tracker'!$O9="🟡 TODAY"),9,"")) | B10: =IF('📖 Review Tracker'!$C9="","",IF(OR('📖 Review Tracker'!$O9="🔴 OVERDUE",'📖 Review Tracker'!$O9="🟡 TODAY"),'📖 Review Tracker'!$A9,"")) | C10: =IF('📖 Review Tracker'!$C9="","",IF(OR('📖 Review Tracker'!$O9="🔴 OVERDUE",'📖 Review Tracker'!$O9="🟡 TODAY"),'📖 Review Tracker'!$C9,"")) | D10: =IF('📖 Review Tracker'!$C9="","",IF(OR('📖 Review Tracker'!$O9="🔴 OVERDUE",'📖 Review Tracker'!$O9="🟡 TODAY"),TEXT('📖 Review Tracker'!$M9,"DD/MM/YYYY"),"")) | E10: =IF('📖 Review Tracker'!$C9="","",IF(OR('📖 Review Tracker'!$O9="🔴 OVERDUE",'📖 Review Tracker'!$O9="🟡 TODAY"),'📖 Review Tracker'!$N9,"")) | F10: =IF('📖 Review Tracker'!$C9="","",IF(OR('📖 Review Tracker'!$O9="🔴 OVERDUE",'📖 Review Tracker'!$O9="🟡 TODAY"),IF('📖 Review Tracker'!$F9="","J1",IF('📖 Review Tracker'!$G9="","J3",IF('📖 Review Tracker'!$H9="","J7",IF('📖 Review Tracker'!$I9="","J15",IF('📖 Review Tracker'!$J9="","J30",IF('📖 Review Tracker'!$K9="","J60","J90")))))),"")) | G10: =IF('📖 Review Tracker'!$C9="","",IF(OR('📖 Review Tracker'!$O9="🔴 OVERDUE",'📖 Review Tracker'!$O9="🟡 TODAY"),'📖 Review Tracker'!$O9,"")) | H10: =IF(I10="✅ Done",TEXT(TODAY(),"DD/MM/YYYY"),"")
A11: =IF('📖 Review Tracker'!$C10="","",IF(OR('📖 Review Tracker'!$O10="🔴 OVERDUE",'📖 Review Tracker'!$O10="🟡 TODAY"),10,"")) | B11: =IF('📖 Review Tracker'!$C10="","",IF(OR('📖 Review Tracker'!$O10="🔴 OVERDUE",'📖 Review Tracker'!$O10="🟡 TODAY"),'📖 Review Tracker'!$A10,"")) | C11: =IF('📖 Review Tracker'!$C10="","",IF(OR('📖 Review Tracker'!$O10="🔴 OVERDUE",'📖 Review Tracker'!$O10="🟡 TODAY"),'📖 Review Tracker'!$C10,"")) | D11: =IF('📖 Review Tracker'!$C10="","",IF(OR('📖 Review Tracker'!$O10="🔴 OVERDUE",'📖 Review Tracker'!$O10="🟡 TODAY"),TEXT('📖 Review Tracker'!$M10,"DD/MM/YYYY"),"")) | E11: =IF('📖 Review Tracker'!$C10="","",IF(OR('📖 Review Tracker'!$O10="🔴 OVERDUE",'📖 Review Tracker'!$O10="🟡 TODAY"),'📖 Review Tracker'!$N10,"")) | F11: =IF('📖 Review Tracker'!$C10="","",IF(OR('📖 Review Tracker'!$O10="🔴 OVERDUE",'📖 Review Tracker'!$O10="🟡 TODAY"),IF('📖 Review Tracker'!$F10="","J1",IF('📖 Review Tracker'!$G10="","J3",IF('📖 Review Tracker'!$H10="","J7",IF('📖 Review Tracker'!$I10="","J15",IF('📖 Review Tracker'!$J10="","J30",IF('📖 Review Tracker'!$K10="","J60","J90")))))),"")) | G11: =IF('📖 Review Tracker'!$C10="","",IF(OR('📖 Review Tracker'!$O10="🔴 OVERDUE",'📖 Review Tracker'!$O10="🟡 TODAY"),'📖 Review Tracker'!$O10,"")) | H11: =IF(I11="✅ Done",TEXT(TODAY(),"DD/MM/YYYY"),"")
A12: =IF('📖 Review Tracker'!$C11="","",IF(OR('📖 Review Tracker'!$O11="🔴 OVERDUE",'📖 Review Tracker'!$O11="🟡 TODAY"),11,"")) | B12: =IF('📖 Review Tracker'!$C11="","",IF(OR('📖 Review Tracker'!$O11="🔴 OVERDUE",'📖 Review Tracker'!$O11="🟡 TODAY"),'📖 Review Tracker'!$A11,"")) | C12: =IF('📖 Review Tracker'!$C11="","",IF(OR('📖 Review Tracker'!$O11="🔴 OVERDUE",'📖 Review Tracker'!$O11="🟡 TODAY"),'📖 Review Tracker'!$C11,"")) | D12: =IF('📖 Review Tracker'!$C11="","",IF(OR('📖 Review Tracker'!$O11="🔴 OVERDUE",'📖 Review Tracker'!$O11="🟡 TODAY"),TEXT('📖 Review Tracker'!$M11,"DD/MM/YYYY"),"")) | E12: =IF('📖 Review Tracker'!$C11="","",IF(OR('📖 Review Tracker'!$O11="🔴 OVERDUE",'📖 Review Tracker'!$O11="🟡 TODAY"),'📖 Review Tracker'!$N11,"")) | F12: =IF('📖 Review Tracker'!$C11="","",IF(OR('📖 Review Tracker'!$O11="🔴 OVERDUE",'📖 Review Tracker'!$O11="🟡 TODAY"),IF('📖 Review Tracker'!$F11="","J1",IF('📖 Review Tracker'!$G11="","J3",IF('📖 Review Tracker'!$H11="","J7",IF('📖 Review Tracker'!$I11="","J15",IF('📖 Review Tracker'!$J11="","J30",IF('📖 Review Tracker'!$K11="","J60","J90")))))),"")) | G12: =IF('📖 Review Tracker'!$C11="","",IF(OR('📖 Review Tracker'!$O11="🔴 OVERDUE",'📖 Review Tracker'!$O11="🟡 TODAY"),'📖 Review Tracker'!$O11,"")) | H12: =IF(I12="✅ Done",TEXT(TODAY(),"DD/MM/YYYY"),"")
A13: =IF('📖 Review Tracker'!$C12="","",IF(OR('📖 Review Tracker'!$O12="🔴 OVERDUE",'📖 Review Tracker'!$O12="🟡 TODAY"),12,"")) | B13: =IF('📖 Review Tracker'!$C12="","",IF(OR('📖 Review Tracker'!$O12="🔴 OVERDUE",'📖 Review Tracker'!$O12="🟡 TODAY"),'📖 Review Tracker'!$A12,"")) | C13: =IF('📖 Review Tracker'!$C12="","",IF(OR('📖 Review Tracker'!$O12="🔴 OVERDUE",'📖 Review Tracker'!$O12="🟡 TODAY"),'📖 Review Tracker'!$C12,"")) | D13: =IF('📖 Review Tracker'!$C12="","",IF(OR('📖 Review Tracker'!$O12="🔴 OVERDUE",'📖 Review Tracker'!$O12="🟡 TODAY"),TEXT('📖 Review Tracker'!$M12,"DD/MM/YYYY"),"")) | E13: =IF('📖 Review Tracker'!$C12="","",IF(OR('📖 Review Tracker'!$O12="🔴 OVERDUE",'📖 Review Tracker'!$O12="🟡 TODAY"),'📖 Review Tracker'!$N12,"")) | F13: =IF('📖 Review Tracker'!$C12="","",IF(OR('📖 Review Tracker'!$O12="🔴 OVERDUE",'📖 Review Tracker'!$O12="🟡 TODAY"),IF('📖 Review Tracker'!$F12="","J1",IF('📖 Review Tracker'!$G12="","J3",IF('📖 Review Tracker'!$H12="","J7",IF('📖 Review Tracker'!$I12="","J15",IF('📖 Review Tracker'!$J12="","J30",IF('📖 Review Tracker'!$K12="","J60","J90")))))),"")) | G13: =IF('📖 Review Tracker'!$C12="","",IF(OR('📖 Review Tracker'!$O12="🔴 OVERDUE",'📖 Review Tracker'!$O12="🟡 TODAY"),'📖 Review Tracker'!$O12,"")) | H13: =IF(I13="✅ Done",TEXT(TODAY(),"DD/MM/YYYY"),"")
A14: =IF('📖 Review Tracker'!$C13="","",IF(OR('📖 Review Tracker'!$O13="🔴 OVERDUE",'📖 Review Tracker'!$O13="🟡 TODAY"),13,"")) | B14: =IF('📖 Review Tracker'!$C13="","",IF(OR('📖 Review Tracker'!$O13="🔴 OVERDUE",'📖 Review Tracker'!$O13="🟡 TODAY"),'📖 Review Tracker'!$A13,"")) | C14: =IF('📖 Review Tracker'!$C13="","",IF(OR('📖 Review Tracker'!$O13="🔴 OVERDUE",'📖 Review Tracker'!$O13="🟡 TODAY"),'📖 Review Tracker'!$C13,"")) | D14: =IF('📖 Review Tracker'!$C13="","",IF(OR('📖 Review Tracker'!$O13="🔴 OVERDUE",'📖 Review Tracker'!$O13="🟡 TODAY"),TEXT('📖 Review Tracker'!$M13,"DD/MM/YYYY"),"")) | E14: =IF('📖 Review Tracker'!$C13="","",IF(OR('📖 Review Tracker'!$O13="🔴 OVERDUE",'📖 Review Tracker'!$O13="🟡 TODAY"),'📖 Review Tracker'!$N13,"")) | F14: =IF('📖 Review Tracker'!$C13="","",IF(OR('📖 Review Tracker'!$O13="🔴 OVERDUE",'📖 Review Tracker'!$O13="🟡 TODAY"),IF('📖 Review Tracker'!$F13="","J1",IF('📖 Review Tracker'!$G13="","J3",IF('📖 Review Tracker'!$H13="","J7",IF('📖 Review Tracker'!$I13="","J15",IF('📖 Review Tracker'!$J13="","J30",IF('📖 Review Tracker'!$K13="","J60","J90")))))),"")) | G14: =IF('📖 Review Tracker'!$C13="","",IF(OR('📖 Review Tracker'!$O13="🔴 OVERDUE",'📖 Review Tracker'!$O13="🟡 TODAY"),'📖 Review Tracker'!$O13,"")) | H14: =IF(I14="✅ Done",TEXT(TODAY(),"DD/MM/YYYY"),"")
A15: =IF('📖 Review Tracker'!$C14="","",IF(OR('📖 Review Tracker'!$O14="🔴 OVERDUE",'📖 Review Tracker'!$O14="🟡 TODAY"),14,"")) | B15: =IF('📖 Review Tracker'!$C14="","",IF(OR('📖 Review Tracker'!$O14="🔴 OVERDUE",'📖 Review Tracker'!$O14="🟡 TODAY"),'📖 Review Tracker'!$A14,"")) | C15: =IF('📖 Review Tracker'!$C14="","",IF(OR('📖 Review Tracker'!$O14="🔴 OVERDUE",'📖 Review Tracker'!$O14="🟡 TODAY"),'📖 Review Tracker'!$C14,"")) | D15: =IF('📖 Review Tracker'!$C14="","",IF(OR('📖 Review Tracker'!$O14="🔴 OVERDUE",'📖 Review Tracker'!$O14="🟡 TODAY"),TEXT('📖 Review Tracker'!$M14,"DD/MM/YYYY"),"")) | E15: =IF('📖 Review Tracker'!$C14="","",IF(OR('📖 Review Tracker'!$O14="🔴 OVERDUE",'📖 Review Tracker'!$O14="🟡 TODAY"),'📖 Review Tracker'!$N14,"")) | F15: =IF('📖 Review Tracker'!$C14="","",IF(OR('📖 Review Tracker'!$O14="🔴 OVERDUE",'📖 Review Tracker'!$O14="🟡 TODAY"),IF('📖 Review Tracker'!$F14="","J1",IF('📖 Review Tracker'!$G14="","J3",IF('📖 Review Tracker'!$H14="","J7",IF('📖 Review Tracker'!$I14="","J15",IF('📖 Review Tracker'!$J14="","J30",IF('📖 Review Tracker'!$K14="","J60","J90")))))),"")) | G15: =IF('📖 Review Tracker'!$C14="","",IF(OR('📖 Review Tracker'!$O14="🔴 OVERDUE",'📖 Review Tracker'!$O14="🟡 TODAY"),'📖 Review Tracker'!$O14,"")) | H15: =IF(I15="✅ Done",TEXT(TODAY(),"DD/MM/YYYY"),"")
A16: =IF('📖 Review Tracker'!$C15="","",IF(OR('📖 Review Tracker'!$O15="🔴 OVERDUE",'📖 Review Tracker'!$O15="🟡 TODAY"),15,"")) | B16: =IF('📖 Review Tracker'!$C15="","",IF(OR('📖 Review Tracker'!$O15="🔴 OVERDUE",'📖 Review Tracker'!$O15="🟡 TODAY"),'📖 Review Tracker'!$A15,"")) | C16: =IF('📖 Review Tracker'!$C15="","",IF(OR('📖 Review Tracker'!$O15="🔴 OVERDUE",'📖 Review Tracker'!$O15="🟡 TODAY"),'📖 Review Tracker'!$C15,"")) | D16: =IF('📖 Review Tracker'!$C15="","",IF(OR('📖 Review Tracker'!$O15="🔴 OVERDUE",'📖 Review Tracker'!$O15="🟡 TODAY"),TEXT('📖 Review Tracker'!$M15,"DD/MM/YYYY"),"")) | E16: =IF('📖 Review Tracker'!$C15="","",IF(OR('📖 Review Tracker'!$O15="🔴 OVERDUE",'📖 Review Tracker'!$O15="🟡 TODAY"),'📖 Review Tracker'!$N15,"")) | F16: =IF('📖 Review Tracker'!$C15="","",IF(OR('📖 Review Tracker'!$O15="🔴 OVERDUE",'📖 Review Tracker'!$O15="🟡 TODAY"),IF('📖 Review Tracker'!$F15="","J1",IF('📖 Review Tracker'!$G15="","J3",IF('📖 Review Tracker'!$H15="","J7",IF('📖 Review Tracker'!$I15="","J15",IF('📖 Review Tracker'!$J15="","J30",IF('📖 Review Tracker'!$K15="","J60","J90")))))),"")) | G16: =IF('📖 Review Tracker'!$C15="","",IF(OR('📖 Review Tracker'!$O15="🔴 OVERDUE",'📖 Review Tracker'!$O15="🟡 TODAY"),'📖 Review Tracker'!$O15,"")) | H16: =IF(I16="✅ Done",TEXT(TODAY(),"DD/MM/YYYY"),"")
A17: =IF('📖 Review Tracker'!$C16="","",IF(OR('📖 Review Tracker'!$O16="🔴 OVERDUE",'📖 Review Tracker'!$O16="🟡 TODAY"),16,"")) | B17: =IF('📖 Review Tracker'!$C16="","",IF(OR('📖 Review Tracker'!$O16="🔴 OVERDUE",'📖 Review Tracker'!$O16="🟡 TODAY"),'📖 Review Tracker'!$A16,"")) | C17: =IF('📖 Review Tracker'!$C16="","",IF(OR('📖 Review Tracker'!$O16="🔴 OVERDUE",'📖 Review Tracker'!$O16="🟡 TODAY"),'📖 Review Tracker'!$C16,"")) | D17: =IF('📖 Review Tracker'!$C16="","",IF(OR('📖 Review Tracker'!$O16="🔴 OVERDUE",'📖 Review Tracker'!$O16="🟡 TODAY"),TEXT('📖 Review Tracker'!$M16,"DD/MM/YYYY"),"")) | E17: =IF('📖 Review Tracker'!$C16="","",IF(OR('📖 Review Tracker'!$O16="🔴 OVERDUE",'📖 Review Tracker'!$O16="🟡 TODAY"),'📖 Review Tracker'!$N16,"")) | F17: =IF('📖 Review Tracker'!$C16="","",IF(OR('📖 Review Tracker'!$O16="🔴 OVERDUE",'📖 Review Tracker'!$O16="🟡 TODAY"),IF('📖 Review Tracker'!$F16="","J1",IF('📖 Review Tracker'!$G16="","J3",IF('📖 Review Tracker'!$H16="","J7",IF('📖 Review Tracker'!$I16="","J15",IF('📖 Review Tracker'!$J16="","J30",IF('📖 Review Tracker'!$K16="","J60","J90")))))),"")) | G17: =IF('📖 Review Tracker'!$C16="","",IF(OR('📖 Review Tracker'!$O16="🔴 OVERDUE",'📖 Review Tracker'!$O16="🟡 TODAY"),'📖 Review Tracker'!$O16,"")) | H17: =IF(I17="✅ Done",TEXT(TODAY(),"DD/MM/YYYY"),"")
A18: =IF('📖 Review Tracker'!$C17="","",IF(OR('📖 Review Tracker'!$O17="🔴 OVERDUE",'📖 Review Tracker'!$O17="🟡 TODAY"),17,"")) | B18: =IF('📖 Review Tracker'!$C17="","",IF(OR('📖 Review Tracker'!$O17="🔴 OVERDUE",'📖 Review Tracker'!$O17="🟡 TODAY"),'📖 Review Tracker'!$A17,"")) | C18: =IF('📖 Review Tracker'!$C17="","",IF(OR('📖 Review Tracker'!$O17="🔴 OVERDUE",'📖 Review Tracker'!$O17="🟡 TODAY"),'📖 Review Tracker'!$C17,"")) | D18: =IF('📖 Review Tracker'!$C17="","",IF(OR('📖 Review Tracker'!$O17="🔴 OVERDUE",'📖 Review Tracker'!$O17="🟡 TODAY"),TEXT('📖 Review Tracker'!$M17,"DD/MM/YYYY"),"")) | E18: =IF('📖 Review Tracker'!$C17="","",IF(OR('📖 Review Tracker'!$O17="🔴 OVERDUE",'📖 Review Tracker'!$O17="🟡 TODAY"),'📖 Review Tracker'!$N17,"")) | F18: =IF('📖 Review Tracker'!$C17="","",IF(OR('📖 Review Tracker'!$O17="🔴 OVERDUE",'📖 Review Tracker'!$O17="🟡 TODAY"),IF('📖 Review Tracker'!$F17="","J1",IF('📖 Review Tracker'!$G17="","J3",IF('📖 Review Tracker'!$H17="","J7",IF('📖 Review Tracker'!$I17="","J15",IF('📖 Review Tracker'!$J17="","J30",IF('📖 Review Tracker'!$K17="","J60","J90")))))),"")) | G18: =IF('📖 Review Tracker'!$C17="","",IF(OR('📖 Review Tracker'!$O17="🔴 OVERDUE",'📖 Review Tracker'!$O17="🟡 TODAY"),'📖 Review Tracker'!$O17,"")) | H18: =IF(I18="✅ Done",TEXT(TODAY(),"DD/MM/YYYY"),"")
A19: =IF('📖 Review Tracker'!$C18="","",IF(OR('📖 Review Tracker'!$O18="🔴 OVERDUE",'📖 Review Tracker'!$O18="🟡 TODAY"),18,"")) | B19: =IF('📖 Review Tracker'!$C18="","",IF(OR('📖 Review Tracker'!$O18="🔴 OVERDUE",'📖 Review Tracker'!$O18="🟡 TODAY"),'📖 Review Tracker'!$A18,"")) | C19: =IF('📖 Review Tracker'!$C18="","",IF(OR('📖 Review Tracker'!$O18="🔴 OVERDUE",'📖 Review Tracker'!$O18="🟡 TODAY"),'📖 Review Tracker'!$C18,"")) | D19: =IF('📖 Review Tracker'!$C18="","",IF(OR('📖 Review Tracker'!$O18="🔴 OVERDUE",'📖 Review Tracker'!$O18="🟡 TODAY"),TEXT('📖 Review Tracker'!$M18,"DD/MM/YYYY"),"")) | E19: =IF('📖 Review Tracker'!$C18="","",IF(OR('📖 Review Tracker'!$O18="🔴 OVERDUE",'📖 Review Tracker'!$O18="🟡 TODAY"),'📖 Review Tracker'!$N18,"")) | F19: =IF('📖 Review Tracker'!$C18="","",IF(OR('📖 Review Tracker'!$O18="🔴 OVERDUE",'📖 Review Tracker'!$O18="🟡 TODAY"),IF('📖 Review Tracker'!$F18="","J1",IF('📖 Review Tracker'!$G18="","J3",IF('📖 Review Tracker'!$H18="","J7",IF('📖 Review Tracker'!$I18="","J15",IF('📖 Review Tracker'!$J18="","J30",IF('📖 Review Tracker'!$K18="","J60","J90")))))),"")) | G19: =IF('📖 Review Tracker'!$C18="","",IF(OR('📖 Review Tracker'!$O18="🔴 OVERDUE",'📖 Review Tracker'!$O18="🟡 TODAY"),'📖 Review Tracker'!$O18,"")) | H19: =IF(I19="✅ Done",TEXT(TODAY(),"DD/MM/YYYY"),"")
A20: =IF('📖 Review Tracker'!$C19="","",IF(OR('📖 Review Tracker'!$O19="🔴 OVERDUE",'📖 Review Tracker'!$O19="🟡 TODAY"),19,"")) | B20: =IF('📖 Review Tracker'!$C19="","",IF(OR('📖 Review Tracker'!$O19="🔴 OVERDUE",'📖 Review Tracker'!$O19="🟡 TODAY"),'📖 Review Tracker'!$A19,"")) | C20: =IF('📖 Review Tracker'!$C19="","",IF(OR('📖 Review Tracker'!$O19="🔴 OVERDUE",'📖 Review Tracker'!$O19="🟡 TODAY"),'📖 Review Tracker'!$C19,"")) | D20: =IF('📖 Review Tracker'!$C19="","",IF(OR('📖 Review Tracker'!$O19="🔴 OVERDUE",'📖 Review Tracker'!$O19="🟡 TODAY"),TEXT('📖 Review Tracker'!$M19,"DD/MM/YYYY"),"")) | E20: =IF('📖 Review Tracker'!$C19="","",IF(OR('📖 Review Tracker'!$O19="🔴 OVERDUE",'📖 Review Tracker'!$O19="🟡 TODAY"),'📖 Review Tracker'!$N19,"")) | F20: =IF('📖 Review Tracker'!$C19="","",IF(OR('📖 Review Tracker'!$O19="🔴 OVERDUE",'📖 Review Tracker'!$O19="🟡 TODAY"),IF('📖 Review Tracker'!$F19="","J1",IF('📖 Review Tracker'!$G19="","J3",IF('📖 Review Tracker'!$H19="","J7",IF('📖 Review Tracker'!$I19="","J15",IF('📖 Review Tracker'!$J19="","J30",IF('📖 Review Tracker'!$K19="","J60","J90")))))),"")) | G20: =IF('📖 Review Tracker'!$C19="","",IF(OR('📖 Review Tracker'!$O19="🔴 OVERDUE",'📖 Review Tracker'!$O19="🟡 TODAY"),'📖 Review Tracker'!$O19,"")) | H20: =IF(I20="✅ Done",TEXT(TODAY(),"DD/MM/YYYY"),"")
A21: =IF('📖 Review Tracker'!$C20="","",IF(OR('📖 Review Tracker'!$O20="🔴 OVERDUE",'📖 Review Tracker'!$O20="🟡 TODAY"),20,"")) | B21: =IF('📖 Review Tracker'!$C20="","",IF(OR('📖 Review Tracker'!$O20="🔴 OVERDUE",'📖 Review Tracker'!$O20="🟡 TODAY"),'📖 Review Tracker'!$A20,"")) | C21: =IF('📖 Review Tracker'!$C20="","",IF(OR('📖 Review Tracker'!$O20="🔴 OVERDUE",'📖 Review Tracker'!$O20="🟡 TODAY"),'📖 Review Tracker'!$C20,"")) | D21: =IF('📖 Review Tracker'!$C20="","",IF(OR('📖 Review Tracker'!$O20="🔴 OVERDUE",'📖 Review Tracker'!$O20="🟡 TODAY"),TEXT('📖 Review Tracker'!$M20,"DD/MM/YYYY"),"")) | E21: =IF('📖 Review Tracker'!$C20="","",IF(OR('📖 Review Tracker'!$O20="🔴 OVERDUE",'📖 Review Tracker'!$O20="🟡 TODAY"),'📖 Review Tracker'!$N20,"")) | F21: =IF('📖 Review Tracker'!$C20="","",IF(OR('📖 Review Tracker'!$O20="🔴 OVERDUE",'📖 Review Tracker'!$O20="🟡 TODAY"),IF('📖 Review Tracker'!$F20="","J1",IF('📖 Review Tracker'!$G20="","J3",IF('📖 Review Tracker'!$H20="","J7",IF('📖 Review Tracker'!$I20="","J15",IF('📖 Review Tracker'!$J20="","J30",IF('📖 Review Tracker'!$K20="","J60","J90")))))),"")) | G21: =IF('📖 Review Tracker'!$C20="","",IF(OR('📖 Review Tracker'!$O20="🔴 OVERDUE",'📖 Review Tracker'!$O20="🟡 TODAY"),'📖 Review Tracker'!$O20,"")) | H21: =IF(I21="✅ Done",TEXT(TODAY(),"DD/MM/YYYY"),"")
A22: =IF('📖 Review Tracker'!$C21="","",IF(OR('📖 Review Tracker'!$O21="🔴 OVERDUE",'📖 Review Tracker'!$O21="🟡 TODAY"),21,"")) | B22: =IF('📖 Review Tracker'!$C21="","",IF(OR('📖 Review Tracker'!$O21="🔴 OVERDUE",'📖 Review Tracker'!$O21="🟡 TODAY"),'📖 Review Tracker'!$A21,"")) | C22: =IF('📖 Review Tracker'!$C21="","",IF(OR('📖 Review Tracker'!$O21="🔴 OVERDUE",'📖 Review Tracker'!$O21="🟡 TODAY"),'📖 Review Tracker'!$C21,"")) | D22: =IF('📖 Review Tracker'!$C21="","",IF(OR('📖 Review Tracker'!$O21="🔴 OVERDUE",'📖 Review Tracker'!$O21="🟡 TODAY"),TEXT('📖 Review Tracker'!$M21,"DD/MM/YYYY"),"")) | E22: =IF('📖 Review Tracker'!$C21="","",IF(OR('📖 Review Tracker'!$O21="🔴 OVERDUE",'📖 Review Tracker'!$O21="🟡 TODAY"),'📖 Review Tracker'!$N21,"")) | F22: =IF('📖 Review Tracker'!$C21="","",IF(OR('📖 Review Tracker'!$O21="🔴 OVERDUE",'📖 Review Tracker'!$O21="🟡 TODAY"),IF('📖 Review Tracker'!$F21="","J1",IF('📖 Review Tracker'!$G21="","J3",IF('📖 Review Tracker'!$H21="","J7",IF('📖 Review Tracker'!$I21="","J15",IF('📖 Review Tracker'!$J21="","J30",IF('📖 Review Tracker'!$K21="","J60","J90")))))),"")) | G22: =IF('📖 Review Tracker'!$C21="","",IF(OR('📖 Review Tracker'!$O21="🔴 OVERDUE",'📖 Review Tracker'!$O21="🟡 TODAY"),'📖 Review Tracker'!$O21,"")) | H22: =IF(I22="✅ Done",TEXT(TODAY(),"DD/MM/YYYY"),"")
A23: =IF('📖 Review Tracker'!$C22="","",IF(OR('📖 Review Tracker'!$O22="🔴 OVERDUE",'📖 Review Tracker'!$O22="🟡 TODAY"),22,"")) | B23: =IF('📖 Review Tracker'!$C22="","",IF(OR('📖 Review Tracker'!$O22="🔴 OVERDUE",'📖 Review Tracker'!$O22="🟡 TODAY"),'📖 Review Tracker'!$A22,"")) | C23: =IF('📖 Review Tracker'!$C22="","",IF(OR('📖 Review Tracker'!$O22="🔴 OVERDUE",'📖 Review Tracker'!$O22="🟡 TODAY"),'📖 Review Tracker'!$C22,"")) | D23: =IF('📖 Review Tracker'!$C22="","",IF(OR('📖 Review Tracker'!$O22="🔴 OVERDUE",'📖 Review Tracker'!$O22="🟡 TODAY"),TEXT('📖 Review Tracker'!$M22,"DD/MM/YYYY"),"")) | E23: =IF('📖 Review Tracker'!$C22="","",IF(OR('📖 Review Tracker'!$O22="🔴 OVERDUE",'📖 Review Tracker'!$O22="🟡 TODAY"),'📖 Review Tracker'!$N22,"")) | F23: =IF('📖 Review Tracker'!$C22="","",IF(OR('📖 Review Tracker'!$O22="🔴 OVERDUE",'📖 Review Tracker'!$O22="🟡 TODAY"),IF('📖 Review Tracker'!$F22="","J1",IF('📖 Review Tracker'!$G22="","J3",IF('📖 Review Tracker'!$H22="","J7",IF('📖 Review Tracker'!$I22="","J15",IF('📖 Review Tracker'!$J22="","J30",IF('📖 Review Tracker'!$K22="","J60","J90")))))),"")) | G23: =IF('📖 Review Tracker'!$C22="","",IF(OR('📖 Review Tracker'!$O22="🔴 OVERDUE",'📖 Review Tracker'!$O22="🟡 TODAY"),'📖 Review Tracker'!$O22,"")) | H23: =IF(I23="✅ Done",TEXT(TODAY(),"DD/MM/YYYY"),"")
A24: =IF('📖 Review Tracker'!$C23="","",IF(OR('📖 Review Tracker'!$O23="🔴 OVERDUE",'📖 Review Tracker'!$O23="🟡 TODAY"),23,"")) | B24: =IF('📖 Review Tracker'!$C23="","",IF(OR('📖 Review Tracker'!$O23="🔴 OVERDUE",'📖 Review Tracker'!$O23="🟡 TODAY"),'📖 Review Tracker'!$A23,"")) | C24: =IF('📖 Review Tracker'!$C23="","",IF(OR('📖 Review Tracker'!$O23="🔴 OVERDUE",'📖 Review Tracker'!$O23="🟡 TODAY"),'📖 Review Tracker'!$C23,"")) | D24: =IF('📖 Review Tracker'!$C23="","",IF(OR('📖 Review Tracker'!$O23="🔴 OVERDUE",'📖 Review Tracker'!$O23="🟡 TODAY"),TEXT('📖 Review Tracker'!$M23,"DD/MM/YYYY"),"")) | E24: =IF('📖 Review Tracker'!$C23="","",IF(OR('📖 Review Tracker'!$O23="🔴 OVERDUE",'📖 Review Tracker'!$O23="🟡 TODAY"),'📖 Review Tracker'!$N23,"")) | F24: =IF('📖 Review Tracker'!$C23="","",IF(OR('📖 Review Tracker'!$O23="🔴 OVERDUE",'📖 Review Tracker'!$O23="🟡 TODAY"),IF('📖 Review Tracker'!$F23="","J1",IF('📖 Review Tracker'!$G23="","J3",IF('📖 Review Tracker'!$H23="","J7",IF('📖 Review Tracker'!$I23="","J15",IF('📖 Review Tracker'!$J23="","J30",IF('📖 Review Tracker'!$K23="","J60","J90")))))),"")) | G24: =IF('📖 Review Tracker'!$C23="","",IF(OR('📖 Review Tracker'!$O23="🔴 OVERDUE",'📖 Review Tracker'!$O23="🟡 TODAY"),'📖 Review Tracker'!$O23,"")) | H24: =IF(I24="✅ Done",TEXT(TODAY(),"DD/MM/YYYY"),"")
A25: =IF('📖 Review Tracker'!$C24="","",IF(OR('📖 Review Tracker'!$O24="🔴 OVERDUE",'📖 Review Tracker'!$O24="🟡 TODAY"),24,"")) | B25: =IF('📖 Review Tracker'!$C24="","",IF(OR('📖 Review Tracker'!$O24="🔴 OVERDUE",'📖 Review Tracker'!$O24="🟡 TODAY"),'📖 Review Tracker'!$A24,"")) | C25: =IF('📖 Review Tracker'!$C24="","",IF(OR('📖 Review Tracker'!$O24="🔴 OVERDUE",'📖 Review Tracker'!$O24="🟡 TODAY"),'📖 Review Tracker'!$C24,"")) | D25: =IF('📖 Review Tracker'!$C24="","",IF(OR('📖 Review Tracker'!$O24="🔴 OVERDUE",'📖 Review Tracker'!$O24="🟡 TODAY"),TEXT('📖 Review Tracker'!$M24,"DD/MM/YYYY"),"")) | E25: =IF('📖 Review Tracker'!$C24="","",IF(OR('📖 Review Tracker'!$O24="🔴 OVERDUE",'📖 Review Tracker'!$O24="🟡 TODAY"),'📖 Review Tracker'!$N24,"")) | F25: =IF('📖 Review Tracker'!$C24="","",IF(OR('📖 Review Tracker'!$O24="🔴 OVERDUE",'📖 Review Tracker'!$O24="🟡 TODAY"),IF('📖 Review Tracker'!$F24="","J1",IF('📖 Review Tracker'!$G24="","J3",IF('📖 Review Tracker'!$H24="","J7",IF('📖 Review Tracker'!$I24="","J15",IF('📖 Review Tracker'!$J24="","J30",IF('📖 Review Tracker'!$K24="","J60","J90")))))),"")) | G25: =IF('📖 Review Tracker'!$C24="","",IF(OR('📖 Review Tracker'!$O24="🔴 OVERDUE",'📖 Review Tracker'!$O24="🟡 TODAY"),'📖 Review Tracker'!$O24,"")) | H25: =IF(I25="✅ Done",TEXT(TODAY(),"DD/MM/YYYY"),"")
A26: =IF('📖 Review Tracker'!$C25="","",IF(OR('📖 Review Tracker'!$O25="🔴 OVERDUE",'📖 Review Tracker'!$O25="🟡 TODAY"),25,"")) | B26: =IF('📖 Review Tracker'!$C25="","",IF(OR('📖 Review Tracker'!$O25="🔴 OVERDUE",'📖 Review Tracker'!$O25="🟡 TODAY"),'📖 Review Tracker'!$A25,"")) | C26: =IF('📖 Review Tracker'!$C25="","",IF(OR('📖 Review Tracker'!$O25="🔴 OVERDUE",'📖 Review Tracker'!$O25="🟡 TODAY"),'📖 Review Tracker'!$C25,"")) | D26: =IF('📖 Review Tracker'!$C25="","",IF(OR('📖 Review Tracker'!$O25="🔴 OVERDUE",'📖 Review Tracker'!$O25="🟡 TODAY"),TEXT('📖 Review Tracker'!$M25,"DD/MM/YYYY"),"")) | E26: =IF('📖 Review Tracker'!$C25="","",IF(OR('📖 Review Tracker'!$O25="🔴 OVERDUE",'📖 Review Tracker'!$O25="🟡 TODAY"),'📖 Review Tracker'!$N25,"")) | F26: =IF('📖 Review Tracker'!$C25="","",IF(OR('📖 Review Tracker'!$O25="🔴 OVERDUE",'📖 Review Tracker'!$O25="🟡 TODAY"),IF('📖 Review Tracker'!$F25="","J1",IF('📖 Review Tracker'!$G25="","J3",IF('📖 Review Tracker'!$H25="","J7",IF('📖 Review Tracker'!$I25="","J15",IF('📖 Review Tracker'!$J25="","J30",IF('📖 Review Tracker'!$K25="","J60","J90")))))),"")) | G26: =IF('📖 Review Tracker'!$C25="","",IF(OR('📖 Review Tracker'!$O25="🔴 OVERDUE",'📖 Review Tracker'!$O25="🟡 TODAY"),'📖 Review Tracker'!$O25,"")) | H26: =IF(I26="✅ Done",TEXT(TODAY(),"DD/MM/YYYY"),"")
A27: =IF('📖 Review Tracker'!$C26="","",IF(OR('📖 Review Tracker'!$O26="🔴 OVERDUE",'📖 Review Tracker'!$O26="🟡 TODAY"),26,"")) | B27: =IF('📖 Review Tracker'!$C26="","",IF(OR('📖 Review Tracker'!$O26="🔴 OVERDUE",'📖 Review Tracker'!$O26="🟡 TODAY"),'📖 Review Tracker'!$A26,"")) | C27: =IF('📖 Review Tracker'!$C26="","",IF(OR('📖 Review Tracker'!$O26="🔴 OVERDUE",'📖 Review Tracker'!$O26="🟡 TODAY"),'📖 Review Tracker'!$C26,"")) | D27: =IF('📖 Review Tracker'!$C26="","",IF(OR('📖 Review Tracker'!$O26="🔴 OVERDUE",'📖 Review Tracker'!$O26="🟡 TODAY"),TEXT('📖 Review Tracker'!$M26,"DD/MM/YYYY"),"")) | E27: =IF('📖 Review Tracker'!$C26="","",IF(OR('📖 Review Tracker'!$O26="🔴 OVERDUE",'📖 Review Tracker'!$O26="🟡 TODAY"),'📖 Review Tracker'!$N26,"")) | F27: =IF('📖 Review Tracker'!$C26="","",IF(OR('📖 Review Tracker'!$O26="🔴 OVERDUE",'📖 Review Tracker'!$O26="🟡 TODAY"),IF('📖 Review Tracker'!$F26="","J1",IF('📖 Review Tracker'!$G26="","J3",IF('📖 Review Tracker'!$H26="","J7",IF('📖 Review Tracker'!$I26="","J15",IF('📖 Review Tracker'!$J26="","J30",IF('📖 Review Tracker'!$K26="","J60","J90")))))),"")) | G27: =IF('📖 Review Tracker'!$C26="","",IF(OR('📖 Review Tracker'!$O26="🔴 OVERDUE",'📖 Review Tracker'!$O26="🟡 TODAY"),'📖 Review Tracker'!$O26,"")) | H27: =IF(I27="✅ Done",TEXT(TODAY(),"DD/MM/YYYY"),"")
A28: =IF('📖 Review Tracker'!$C27="","",IF(OR('📖 Review Tracker'!$O27="🔴 OVERDUE",'📖 Review Tracker'!$O27="🟡 TODAY"),27,"")) | B28: =IF('📖 Review Tracker'!$C27="","",IF(OR('📖 Review Tracker'!$O27="🔴 OVERDUE",'📖 Review Tracker'!$O27="🟡 TODAY"),'📖 Review Tracker'!$A27,"")) | C28: =IF('📖 Review Tracker'!$C27="","",IF(OR('📖 Review Tracker'!$O27="🔴 OVERDUE",'📖 Review Tracker'!$O27="🟡 TODAY"),'📖 Review Tracker'!$C27,"")) | D28: =IF('📖 Review Tracker'!$C27="","",IF(OR('📖 Review Tracker'!$O27="🔴 OVERDUE",'📖 Review Tracker'!$O27="🟡 TODAY"),TEXT('📖 Review Tracker'!$M27,"DD/MM/YYYY"),"")) | E28: =IF('📖 Review Tracker'!$C27="","",IF(OR('📖 Review Tracker'!$O27="🔴 OVERDUE",'📖 Review Tracker'!$O27="🟡 TODAY"),'📖 Review Tracker'!$N27,"")) | F28: =IF('📖 Review Tracker'!$C27="","",IF(OR('📖 Review Tracker'!$O27="🔴 OVERDUE",'📖 Review Tracker'!$O27="🟡 TODAY"),IF('📖 Review Tracker'!$F27="","J1",IF('📖 Review Tracker'!$G27="","J3",IF('📖 Review Tracker'!$H27="","J7",IF('📖 Review Tracker'!$I27="","J15",IF('📖 Review Tracker'!$J27="","J30",IF('📖 Review Tracker'!$K27="","J60","J90")))))),"")) | G28: =IF('📖 Review Tracker'!$C27="","",IF(OR('📖 Review Tracker'!$O27="🔴 OVERDUE",'📖 Review Tracker'!$O27="🟡 TODAY"),'📖 Review Tracker'!$O27,"")) | H28: =IF(I28="✅ Done",TEXT(TODAY(),"DD/MM/YYYY"),"")
A29: =IF('📖 Review Tracker'!$C28="","",IF(OR('📖 Review Tracker'!$O28="🔴 OVERDUE",'📖 Review Tracker'!$O28="🟡 TODAY"),28,"")) | B29: =IF('📖 Review Tracker'!$C28="","",IF(OR('📖 Review Tracker'!$O28="🔴 OVERDUE",'📖 Review Tracker'!$O28="🟡 TODAY"),'📖 Review Tracker'!$A28,"")) | C29: =IF('📖 Review Tracker'!$C28="","",IF(OR('📖 Review Tracker'!$O28="🔴 OVERDUE",'📖 Review Tracker'!$O28="🟡 TODAY"),'📖 Review Tracker'!$C28,"")) | D29: =IF('📖 Review Tracker'!$C28="","",IF(OR('📖 Review Tracker'!$O28="🔴 OVERDUE",'📖 Review Tracker'!$O28="🟡 TODAY"),TEXT('📖 Review Tracker'!$M28,"DD/MM/YYYY"),"")) | E29: =IF('📖 Review Tracker'!$C28="","",IF(OR('📖 Review Tracker'!$O28="🔴 OVERDUE",'📖 Review Tracker'!$O28="🟡 TODAY"),'📖 Review Tracker'!$N28,"")) | F29: =IF('📖 Review Tracker'!$C28="","",IF(OR('📖 Review Tracker'!$O28="🔴 OVERDUE",'📖 Review Tracker'!$O28="🟡 TODAY"),IF('📖 Review Tracker'!$F28="","J1",IF('📖 Review Tracker'!$G28="","J3",IF('📖 Review Tracker'!$H28="","J7",IF('📖 Review Tracker'!$I28="","J15",IF('📖 Review Tracker'!$J28="","J30",IF('📖 Review Tracker'!$K28="","J60","J90")))))),"")) | G29: =IF('📖 Review Tracker'!$C28="","",IF(OR('📖 Review Tracker'!$O28="🔴 OVERDUE",'📖 Review Tracker'!$O28="🟡 TODAY"),'📖 Review Tracker'!$O28,"")) | H29: =IF(I29="✅ Done",TEXT(TODAY(),"DD/MM/YYYY"),"")
A30: =IF('📖 Review Tracker'!$C29="","",IF(OR('📖 Review Tracker'!$O29="🔴 OVERDUE",'📖 Review Tracker'!$O29="🟡 TODAY"),29,"")) | B30: =IF('📖 Review Tracker'!$C29="","",IF(OR('📖 Review Tracker'!$O29="🔴 OVERDUE",'📖 Review Tracker'!$O29="🟡 TODAY"),'📖 Review Tracker'!$A29,"")) | C30: =IF('📖 Review Tracker'!$C29="","",IF(OR('📖 Review Tracker'!$O29="🔴 OVERDUE",'📖 Review Tracker'!$O29="🟡 TODAY"),'📖 Review Tracker'!$C29,"")) | D30: =IF('📖 Review Tracker'!$C29="","",IF(OR('📖 Review Tracker'!$O29="🔴 OVERDUE",'📖 Review Tracker'!$O29="🟡 TODAY"),TEXT('📖 Review Tracker'!$M29,"DD/MM/YYYY"),"")) | E30: =IF('📖 Review Tracker'!$C29="","",IF(OR('📖 Review Tracker'!$O29="🔴 OVERDUE",'📖 Review Tracker'!$O29="🟡 TODAY"),'📖 Review Tracker'!$N29,"")) | F30: =IF('📖 Review Tracker'!$C29="","",IF(OR('📖 Review Tracker'!$O29="🔴 OVERDUE",'📖 Review Tracker'!$O29="🟡 TODAY"),IF('📖 Review Tracker'!$F29="","J1",IF('📖 Review Tracker'!$G29="","J3",IF('📖 Review Tracker'!$H29="","J7",IF('📖 Review Tracker'!$I29="","J15",IF('📖 Review Tracker'!$J29="","J30",IF('📖 Review Tracker'!$K29="","J60","J90")))))),"")) | G30: =IF('📖 Review Tracker'!$C29="","",IF(OR('📖 Review Tracker'!$O29="🔴 OVERDUE",'📖 Review Tracker'!$O29="🟡 TODAY"),'📖 Review Tracker'!$O29,"")) | H30: =IF(I30="✅ Done",TEXT(TODAY(),"DD/MM/YYYY"),"")
A31: =IF('📖 Review Tracker'!$C30="","",IF(OR('📖 Review Tracker'!$O30="🔴 OVERDUE",'📖 Review Tracker'!$O30="🟡 TODAY"),30,"")) | B31: =IF('📖 Review Tracker'!$C30="","",IF(OR('📖 Review Tracker'!$O30="🔴 OVERDUE",'📖 Review Tracker'!$O30="🟡 TODAY"),'📖 Review Tracker'!$A30,"")) | C31: =IF('📖 Review Tracker'!$C30="","",IF(OR('📖 Review Tracker'!$O30="🔴 OVERDUE",'📖 Review Tracker'!$O30="🟡 TODAY"),'📖 Review Tracker'!$C30,"")) | D31: =IF('📖 Review Tracker'!$C30="","",IF(OR('📖 Review Tracker'!$O30="🔴 OVERDUE",'📖 Review Tracker'!$O30="🟡 TODAY"),TEXT('📖 Review Tracker'!$M30,"DD/MM/YYYY"),"")) | E31: =IF('📖 Review Tracker'!$C30="","",IF(OR('📖 Review Tracker'!$O30="🔴 OVERDUE",'📖 Review Tracker'!$O30="🟡 TODAY"),'📖 Review Tracker'!$N30,"")) | F31: =IF('📖 Review Tracker'!$C30="","",IF(OR('📖 Review Tracker'!$O30="🔴 OVERDUE",'📖 Review Tracker'!$O30="🟡 TODAY"),IF('📖 Review Tracker'!$F30="","J1",IF('📖 Review Tracker'!$G30="","J3",IF('📖 Review Tracker'!$H30="","J7",IF('📖 Review Tracker'!$I30="","J15",IF('📖 Review Tracker'!$J30="","J30",IF('📖 Review Tracker'!$K30="","J60","J90")))))),"")) | G31: =IF('📖 Review Tracker'!$C30="","",IF(OR('📖 Review Tracker'!$O30="🔴 OVERDUE",'📖 Review Tracker'!$O30="🟡 TODAY"),'📖 Review Tracker'!$O30,"")) | H31: =IF(I31="✅ Done",TEXT(TODAY(),"DD/MM/YYYY"),"")
A32: =IF('📖 Review Tracker'!$C31="","",IF(OR('📖 Review Tracker'!$O31="🔴 OVERDUE",'📖 Review Tracker'!$O31="🟡 TODAY"),31,"")) | B32: =IF('📖 Review Tracker'!$C31="","",IF(OR('📖 Review Tracker'!$O31="🔴 OVERDUE",'📖 Review Tracker'!$O31="🟡 TODAY"),'📖 Review Tracker'!$A31,"")) | C32: =IF('📖 Review Tracker'!$C31="","",IF(OR('📖 Review Tracker'!$O31="🔴 OVERDUE",'📖 Review Tracker'!$O31="🟡 TODAY"),'📖 Review Tracker'!$C31,"")) | D32: =IF('📖 Review Tracker'!$C31="","",IF(OR('📖 Review Tracker'!$O31="🔴 OVERDUE",'📖 Review Tracker'!$O31="🟡 TODAY"),TEXT('📖 Review Tracker'!$M31,"DD/MM/YYYY"),"")) | E32: =IF('📖 Review Tracker'!$C31="","",IF(OR('📖 Review Tracker'!$O31="🔴 OVERDUE",'📖 Review Tracker'!$O31="🟡 TODAY"),'📖 Review Tracker'!$N31,"")) | F32: =IF('📖 Review Tracker'!$C31="","",IF(OR('📖 Review Tracker'!$O31="🔴 OVERDUE",'📖 Review Tracker'!$O31="🟡 TODAY"),IF('📖 Review Tracker'!$F31="","J1",IF('📖 Review Tracker'!$G31="","J3",IF('📖 Review Tracker'!$H31="","J7",IF('📖 Review Tracker'!$I31="","J15",IF('📖 Review Tracker'!$J31="","J30",IF('📖 Review Tracker'!$K31="","J60","J90")))))),"")) | G32: =IF('📖 Review Tracker'!$C31="","",IF(OR('📖 Review Tracker'!$O31="🔴 OVERDUE",'📖 Review Tracker'!$O31="🟡 TODAY"),'📖 Review Tracker'!$O31,"")) | H32: =IF(I32="✅ Done",TEXT(TODAY(),"DD/MM/YYYY"),"")
A33: =IF('📖 Review Tracker'!$C32="","",IF(OR('📖 Review Tracker'!$O32="🔴 OVERDUE",'📖 Review Tracker'!$O32="🟡 TODAY"),32,"")) | B33: =IF('📖 Review Tracker'!$C32="","",IF(OR('📖 Review Tracker'!$O32="🔴 OVERDUE",'📖 Review Tracker'!$O32="🟡 TODAY"),'📖 Review Tracker'!$A32,"")) | C33: =IF('📖 Review Tracker'!$C32="","",IF(OR('📖 Review Tracker'!$O32="🔴 OVERDUE",'📖 Review Tracker'!$O32="🟡 TODAY"),'📖 Review Tracker'!$C32,"")) | D33: =IF('📖 Review Tracker'!$C32="","",IF(OR('📖 Review Tracker'!$O32="🔴 OVERDUE",'📖 Review Tracker'!$O32="🟡 TODAY"),TEXT('📖 Review Tracker'!$M32,"DD/MM/YYYY"),"")) | E33: =IF('📖 Review Tracker'!$C32="","",IF(OR('📖 Review Tracker'!$O32="🔴 OVERDUE",'📖 Review Tracker'!$O32="🟡 TODAY"),'📖 Review Tracker'!$N32,"")) | F33: =IF('📖 Review Tracker'!$C32="","",IF(OR('📖 Review Tracker'!$O32="🔴 OVERDUE",'📖 Review Tracker'!$O32="🟡 TODAY"),IF('📖 Review Tracker'!$F32="","J1",IF('📖 Review Tracker'!$G32="","J3",IF('📖 Review Tracker'!$H32="","J7",IF('📖 Review Tracker'!$I32="","J15",IF('📖 Review Tracker'!$J32="","J30",IF('📖 Review Tracker'!$K32="","J60","J90")))))),"")) | G33: =IF('📖 Review Tracker'!$C32="","",IF(OR('📖 Review Tracker'!$O32="🔴 OVERDUE",'📖 Review Tracker'!$O32="🟡 TODAY"),'📖 Review Tracker'!$O32,"")) | H33: =IF(I33="✅ Done",TEXT(TODAY(),"DD/MM/YYYY"),"")
A34: =IF('📖 Review Tracker'!$C33="","",IF(OR('📖 Review Tracker'!$O33="🔴 OVERDUE",'📖 Review Tracker'!$O33="🟡 TODAY"),33,"")) | B34: =IF('📖 Review Tracker'!$C33="","",IF(OR('📖 Review Tracker'!$O33="🔴 OVERDUE",'📖 Review Tracker'!$O33="🟡 TODAY"),'📖 Review Tracker'!$A33,"")) | C34: =IF('📖 Review Tracker'!$C33="","",IF(OR('📖 Review Tracker'!$O33="🔴 OVERDUE",'📖 Review Tracker'!$O33="🟡 TODAY"),'📖 Review Tracker'!$C33,"")) | D34: =IF('📖 Review Tracker'!$C33="","",IF(OR('📖 Review Tracker'!$O33="🔴 OVERDUE",'📖 Review Tracker'!$O33="🟡 TODAY"),TEXT('📖 Review Tracker'!$M33,"DD/MM/YYYY"),"")) | E34: =IF('📖 Review Tracker'!$C33="","",IF(OR('📖 Review Tracker'!$O33="🔴 OVERDUE",'📖 Review Tracker'!$O33="🟡 TODAY"),'📖 Review Tracker'!$N33,"")) | F34: =IF('📖 Review Tracker'!$C33="","",IF(OR('📖 Review Tracker'!$O33="🔴 OVERDUE",'📖 Review Tracker'!$O33="🟡 TODAY"),IF('📖 Review Tracker'!$F33="","J1",IF('📖 Review Tracker'!$G33="","J3",IF('📖 Review Tracker'!$H33="","J7",IF('📖 Review Tracker'!$I33="","J15",IF('📖 Review Tracker'!$J33="","J30",IF('📖 Review Tracker'!$K33="","J60","J90")))))),"")) | G34: =IF('📖 Review Tracker'!$C33="","",IF(OR('📖 Review Tracker'!$O33="🔴 OVERDUE",'📖 Review Tracker'!$O33="🟡 TODAY"),'📖 Review Tracker'!$O33,"")) | H34: =IF(I34="✅ Done",TEXT(TODAY(),"DD/MM/YYYY"),"")
A35: =IF('📖 Review Tracker'!$C34="","",IF(OR('📖 Review Tracker'!$O34="🔴 OVERDUE",'📖 Review Tracker'!$O34="🟡 TODAY"),34,"")) | B35: =IF('📖 Review Tracker'!$C34="","",IF(OR('📖 Review Tracker'!$O34="🔴 OVERDUE",'📖 Review Tracker'!$O34="🟡 TODAY"),'📖 Review Tracker'!$A34,"")) | C35: =IF('📖 Review Tracker'!$C34="","",IF(OR('📖 Review Tracker'!$O34="🔴 OVERDUE",'📖 Review Tracker'!$O34="🟡 TODAY"),'📖 Review Tracker'!$C34,"")) | D35: =IF('📖 Review Tracker'!$C34="","",IF(OR('📖 Review Tracker'!$O34="🔴 OVERDUE",'📖 Review Tracker'!$O34="🟡 TODAY"),TEXT('📖 Review Tracker'!$M34,"DD/MM/YYYY"),"")) | E35: =IF('📖 Review Tracker'!$C34="","",IF(OR('📖 Review Tracker'!$O34="🔴 OVERDUE",'📖 Review Tracker'!$O34="🟡 TODAY"),'📖 Review Tracker'!$N34,"")) | F35: =IF('📖 Review Tracker'!$C34="","",IF(OR('📖 Review Tracker'!$O34="🔴 OVERDUE",'📖 Review Tracker'!$O34="🟡 TODAY"),IF('📖 Review Tracker'!$F34="","J1",IF('📖 Review Tracker'!$G34="","J3",IF('📖 Review Tracker'!$H34="","J7",IF('📖 Review Tracker'!$I34="","J15",IF('📖 Review Tracker'!$J34="","J30",IF('📖 Review Tracker'!$K34="","J60","J90")))))),"")) | G35: =IF('📖 Review Tracker'!$C34="","",IF(OR('📖 Review Tracker'!$O34="🔴 OVERDUE",'📖 Review Tracker'!$O34="🟡 TODAY"),'📖 Review Tracker'!$O34,"")) | H35: =IF(I35="✅ Done",TEXT(TODAY(),"DD/MM/YYYY"),"")
A36: =IF('📖 Review Tracker'!$C35="","",IF(OR('📖 Review Tracker'!$O35="🔴 OVERDUE",'📖 Review Tracker'!$O35="🟡 TODAY"),35,"")) | B36: =IF('📖 Review Tracker'!$C35="","",IF(OR('📖 Review Tracker'!$O35="🔴 OVERDUE",'📖 Review Tracker'!$O35="🟡 TODAY"),'📖 Review Tracker'!$A35,"")) | C36: =IF('📖 Review Tracker'!$C35="","",IF(OR('📖 Review Tracker'!$O35="🔴 OVERDUE",'📖 Review Tracker'!$O35="🟡 TODAY"),'📖 Review Tracker'!$C35,"")) | D36: =IF('📖 Review Tracker'!$C35="","",IF(OR('📖 Review Tracker'!$O35="🔴 OVERDUE",'📖 Review Tracker'!$O35="🟡 TODAY"),TEXT('📖 Review Tracker'!$M35,"DD/MM/YYYY"),"")) | E36: =IF('📖 Review Tracker'!$C35="","",IF(OR('📖 Review Tracker'!$O35="🔴 OVERDUE",'📖 Review Tracker'!$O35="🟡 TODAY"),'📖 Review Tracker'!$N35,"")) | F36: =IF('📖 Review Tracker'!$C35="","",IF(OR('📖 Review Tracker'!$O35="🔴 OVERDUE",'📖 Review Tracker'!$O35="🟡 TODAY"),IF('📖 Review Tracker'!$F35="","J1",IF('📖 Review Tracker'!$G35="","J3",IF('📖 Review Tracker'!$H35="","J7",IF('📖 Review Tracker'!$I35="","J15",IF('📖 Review Tracker'!$J35="","J30",IF('📖 Review Tracker'!$K35="","J60","J90")))))),"")) | G36: =IF('📖 Review Tracker'!$C35="","",IF(OR('📖 Review Tracker'!$O35="🔴 OVERDUE",'📖 Review Tracker'!$O35="🟡 TODAY"),'📖 Review Tracker'!$O35,"")) | H36: =IF(I36="✅ Done",TEXT(TODAY(),"DD/MM/YYYY"),"")
A37: =IF('📖 Review Tracker'!$C36="","",IF(OR('📖 Review Tracker'!$O36="🔴 OVERDUE",'📖 Review Tracker'!$O36="🟡 TODAY"),36,"")) | B37: =IF('📖 Review Tracker'!$C36="","",IF(OR('📖 Review Tracker'!$O36="🔴 OVERDUE",'📖 Review Tracker'!$O36="🟡 TODAY"),'📖 Review Tracker'!$A36,"")) | C37: =IF('📖 Review Tracker'!$C36="","",IF(OR('📖 Review Tracker'!$O36="🔴 OVERDUE",'📖 Review Tracker'!$O36="🟡 TODAY"),'📖 Review Tracker'!$C36,"")) | D37: =IF('📖 Review Tracker'!$C36="","",IF(OR('📖 Review Tracker'!$O36="🔴 OVERDUE",'📖 Review Tracker'!$O36="🟡 TODAY"),TEXT('📖 Review Tracker'!$M36,"DD/MM/YYYY"),"")) | E37: =IF('📖 Review Tracker'!$C36="","",IF(OR('📖 Review Tracker'!$O36="🔴 OVERDUE",'📖 Review Tracker'!$O36="🟡 TODAY"),'📖 Review Tracker'!$N36,"")) | F37: =IF('📖 Review Tracker'!$C36="","",IF(OR('📖 Review Tracker'!$O36="🔴 OVERDUE",'📖 Review Tracker'!$O36="🟡 TODAY"),IF('📖 Review Tracker'!$F36="","J1",IF('📖 Review Tracker'!$G36="","J3",IF('📖 Review Tracker'!$H36="","J7",IF('📖 Review Tracker'!$I36="","J15",IF('📖 Review Tracker'!$J36="","J30",IF('📖 Review Tracker'!$K36="","J60","J90")))))),"")) | G37: =IF('📖 Review Tracker'!$C36="","",IF(OR('📖 Review Tracker'!$O36="🔴 OVERDUE",'📖 Review Tracker'!$O36="🟡 TODAY"),'📖 Review Tracker'!$O36,"")) | H37: =IF(I37="✅ Done",TEXT(TODAY(),"DD/MM/YYYY"),"")
A38: =IF('📖 Review Tracker'!$C37="","",IF(OR('📖 Review Tracker'!$O37="🔴 OVERDUE",'📖 Review Tracker'!$O37="🟡 TODAY"),37,"")) | B38: =IF('📖 Review Tracker'!$C37="","",IF(OR('📖 Review Tracker'!$O37="🔴 OVERDUE",'📖 Review Tracker'!$O37="🟡 TODAY"),'📖 Review Tracker'!$A37,"")) | C38: =IF('📖 Review Tracker'!$C37="","",IF(OR('📖 Review Tracker'!$O37="🔴 OVERDUE",'📖 Review Tracker'!$O37="🟡 TODAY"),'📖 Review Tracker'!$C37,"")) | D38: =IF('📖 Review Tracker'!$C37="","",IF(OR('📖 Review Tracker'!$O37="🔴 OVERDUE",'📖 Review Tracker'!$O37="🟡 TODAY"),TEXT('📖 Review Tracker'!$M37,"DD/MM/YYYY"),"")) | E38: =IF('📖 Review Tracker'!$C37="","",IF(OR('📖 Review Tracker'!$O37="🔴 OVERDUE",'📖 Review Tracker'!$O37="🟡 TODAY"),'📖 Review Tracker'!$N37,"")) | F38: =IF('📖 Review Tracker'!$C37="","",IF(OR('📖 Review Tracker'!$O37="🔴 OVERDUE",'📖 Review Tracker'!$O37="🟡 TODAY"),IF('📖 Review Tracker'!$F37="","J1",IF('📖 Review Tracker'!$G37="","J3",IF('📖 Review Tracker'!$H37="","J7",IF('📖 Review Tracker'!$I37="","J15",IF('📖 Review Tracker'!$J37="","J30",IF('📖 Review Tracker'!$K37="","J60","J90")))))),"")) | G38: =IF('📖 Review Tracker'!$C37="","",IF(OR('📖 Review Tracker'!$O37="🔴 OVERDUE",'📖 Review Tracker'!$O37="🟡 TODAY"),'📖 Review Tracker'!$O37,"")) | H38: =IF(I38="✅ Done",TEXT(TODAY(),"DD/MM/YYYY"),"")
A39: =IF('📖 Review Tracker'!$C38="","",IF(OR('📖 Review Tracker'!$O38="🔴 OVERDUE",'📖 Review Tracker'!$O38="🟡 TODAY"),38,"")) | B39: =IF('📖 Review Tracker'!$C38="","",IF(OR('📖 Review Tracker'!$O38="🔴 OVERDUE",'📖 Review Tracker'!$O38="🟡 TODAY"),'📖 Review Tracker'!$A38,"")) | C39: =IF('📖 Review Tracker'!$C38="","",IF(OR('📖 Review Tracker'!$O38="🔴 OVERDUE",'📖 Review Tracker'!$O38="🟡 TODAY"),'📖 Review Tracker'!$C38,"")) | D39: =IF('📖 Review Tracker'!$C38="","",IF(OR('📖 Review Tracker'!$O38="🔴 OVERDUE",'📖 Review Tracker'!$O38="🟡 TODAY"),TEXT('📖 Review Tracker'!$M38,"DD/MM/YYYY"),"")) | E39: =IF('📖 Review Tracker'!$C38="","",IF(OR('📖 Review Tracker'!$O38="🔴 OVERDUE",'📖 Review Tracker'!$O38="🟡 TODAY"),'📖 Review Tracker'!$N38,"")) | F39: =IF('📖 Review Tracker'!$C38="","",IF(OR('📖 Review Tracker'!$O38="🔴 OVERDUE",'📖 Review Tracker'!$O38="🟡 TODAY"),IF('📖 Review Tracker'!$F38="","J1",IF('📖 Review Tracker'!$G38="","J3",IF('📖 Review Tracker'!$H38="","J7",IF('📖 Review Tracker'!$I38="","J15",IF('📖 Review Tracker'!$J38="","J30",IF('📖 Review Tracker'!$K38="","J60","J90")))))),"")) | G39: =IF('📖 Review Tracker'!$C38="","",IF(OR('📖 Review Tracker'!$O38="🔴 OVERDUE",'📖 Review Tracker'!$O38="🟡 TODAY"),'📖 Review Tracker'!$O38,"")) | H39: =IF(I39="✅ Done",TEXT(TODAY(),"DD/MM/YYYY"),"")
A40: =IF('📖 Review Tracker'!$C39="","",IF(OR('📖 Review Tracker'!$O39="🔴 OVERDUE",'📖 Review Tracker'!$O39="🟡 TODAY"),39,"")) | B40: =IF('📖 Review Tracker'!$C39="","",IF(OR('📖 Review Tracker'!$O39="🔴 OVERDUE",'📖 Review Tracker'!$O39="🟡 TODAY"),'📖 Review Tracker'!$A39,"")) | C40: =IF('📖 Review Tracker'!$C39="","",IF(OR('📖 Review Tracker'!$O39="🔴 OVERDUE",'📖 Review Tracker'!$O39="🟡 TODAY"),'📖 Review Tracker'!$C39,"")) | D40: =IF('📖 Review Tracker'!$C39="","",IF(OR('📖 Review Tracker'!$O39="🔴 OVERDUE",'📖 Review Tracker'!$O39="🟡 TODAY"),TEXT('📖 Review Tracker'!$M39,"DD/MM/YYYY"),"")) | E40: =IF('📖 Review Tracker'!$C39="","",IF(OR('📖 Review Tracker'!$O39="🔴 OVERDUE",'📖 Review Tracker'!$O39="🟡 TODAY"),'📖 Review Tracker'!$N39,"")) | F40: =IF('📖 Review Tracker'!$C39="","",IF(OR('📖 Review Tracker'!$O39="🔴 OVERDUE",'📖 Review Tracker'!$O39="🟡 TODAY"),IF('📖 Review Tracker'!$F39="","J1",IF('📖 Review Tracker'!$G39="","J3",IF('📖 Review Tracker'!$H39="","J7",IF('📖 Review Tracker'!$I39="","J15",IF('📖 Review Tracker'!$J39="","J30",IF('📖 Review Tracker'!$K39="","J60","J90")))))),"")) | G40: =IF('📖 Review Tracker'!$C39="","",IF(OR('📖 Review Tracker'!$O39="🔴 OVERDUE",'📖 Review Tracker'!$O39="🟡 TODAY"),'📖 Review Tracker'!$O39,"")) | H40: =IF(I40="✅ Done",TEXT(TODAY(),"DD/MM/YYYY"),"")
...

Sheet 🔴 Must Complete
A1: 🔴 OVERDUE - ACTION REQUIRED!
A2: Total Overdue: | B2: =COUNTIFS('📖 Review Tracker'!$O:$O,"🔴 OVERDUE") -> 0
A3: ⚠️ These reviews are PAST DUE. Study them immediately! Then enter today's date in the Review Tracker.
A4: # | B4: Category | C4: Lesson | D4: Was Due | E4: Days Late | F4: Review Type | G4: Priority
A5: =IF('📖 Review Tracker'!$O4="🔴 OVERDUE",4,"") | B5: =IF('📖 Review Tracker'!$O4="🔴 OVERDUE",'📖 Review Tracker'!$A4,"") | C5: =IF('📖 Review Tracker'!$O4="🔴 OVERDUE",'📖 Review Tracker'!$C4,"") | D5: =IF('📖 Review Tracker'!$O4="🔴 OVERDUE",TEXT('📖 Review Tracker'!$M4,"DD/MM/YYYY"),"") | E5: =IF('📖 Review Tracker'!$O4="🔴 OVERDUE",'📖 Review Tracker'!$N4,"") | F5: =IF('📖 Review Tracker'!$O4="🔴 OVERDUE",IF('📖 Review Tracker'!$F4="","J1",IF('📖 Review Tracker'!$G4="","J3",IF('📖 Review Tracker'!$H4="","J7",IF('📖 Review Tracker'!$I4="","J15",IF('📖 Review Tracker'!$J4="","J30",IF('📖 Review Tracker'!$K4="","J60","J90")))))),"") | G5: =IF('📖 Review Tracker'!$O4="🔴 OVERDUE","🔴 CRITICAL","")
A6: =IF('📖 Review Tracker'!$O5="🔴 OVERDUE",5,"") | B6: =IF('📖 Review Tracker'!$O5="🔴 OVERDUE",'📖 Review Tracker'!$A5,"") | C6: =IF('📖 Review Tracker'!$O5="🔴 OVERDUE",'📖 Review Tracker'!$C5,"") | D6: =IF('📖 Review Tracker'!$O5="🔴 OVERDUE",TEXT('📖 Review Tracker'!$M5,"DD/MM/YYYY"),"") | E6: =IF('📖 Review Tracker'!$O5="🔴 OVERDUE",'📖 Review Tracker'!$N5,"") | F6: =IF('📖 Review Tracker'!$O5="🔴 OVERDUE",IF('📖 Review Tracker'!$F5="","J1",IF('📖 Review Tracker'!$G5="","J3",IF('📖 Review Tracker'!$H5="","J7",IF('📖 Review Tracker'!$I5="","J15",IF('📖 Review Tracker'!$J5="","J30",IF('📖 Review Tracker'!$K5="","J60","J90")))))),"") | G6: =IF('📖 Review Tracker'!$O5="🔴 OVERDUE","🔴 CRITICAL","")
